Workbook

Sheet Datos
A1: Código AC | B1: Fecha de inicio | C1: Comentarios | D1: Repuesto | E1: Equipo | F1: Activo | G1: Serie
A2: BDG-EQUIO-00015284 | B2: 41942 | C2: -NO_DEFINIDO - se realiza cambio de bombillo de otoscopio equipo queda en correcto funcionamiento | D2: Bombillo | E2: =VLOOKUP(A2,Equipos!$1:$1048576,2,0) -> Equipo Organos De Los Sentidos | F2: 15284 | G2: =VLOOKUP(A2,Equipos!$A$2:$H$16545,4,FALSE) -> N/A
A3: BAN-LARIN-00006779 | B3: 41942 | C3: -NO_DEFINIDO - CREADA DESDE AMsi&#x0D; &#x0D; Se realiza cambio de bombillo de mango de laringoscopio. &#x0D; Se realizan pruebas de funcionamiento &#x0D; Equipo funcionando correctamente | D3: Bombillo | E3: =VLOOKUP(A3,Equipos!$1:$1048576,2,0) -> Laringoscopio | F3: 6779 | G3: =VLOOKUP(A3,Equipos!$A$2:$H$16545,4,FALSE) -> N/A
A4: BAN-LARIN-00015725 | B4: 41942 | C4: -NO_DEFINIDO - CREADA DESDE AMsi&#x0D; &#x0D; Se realiza cambio de bombillo de mango de laringo de la sala 1, se realizan pruebas y equipo queda funcionando | D4: Bombillo | E4: =VLOOKUP(A4,Equipos!$1:$1048576,2,0) -> Laringoscopio | F4: 15725 | G4: =VLOOKUP(A4,Equipos!$A$2:$H$16545,4,FALSE) -> N/A
A5: BMO-TRMOH-00009050 | B5: 41942 | C5: 14/07/2022-NO_DEFINIDO - Solicitud de Servico Creada desde AMSi, 14/07/2022-Novatecnica - la sonda del termohigrometro se encuentra cortada, por lo que se procede a soldar a la tarjeta y se cambia la bateria. Se realizan pruebas y funciona correctamente. | D5: Bateria | E5: =VLOOKUP(A5,Equipos!$1:$1048576,2,0) -> Termohigrometro Digital | F5: 9050 | G5: =VLOOKUP(A5,Equipos!$A$2:$H$16545,4,FALSE) -> N/A
A6: BAN-LARIN-00012366 | B6: 41942 | C6: 21/07/2022-NO_DEFINIDO - Solicitud de Servico Creada desde AMSi, 21/07/2022-Biomedico2 - Se realiza verificación de laringoscopio y se evidencia bombillo dañado Se realiza cambio de bombillo Se entrega al servicio sin novedad | D6: Bombillo | E6: =VLOOKUP(A6,Equipos!$1:$1048576,2,0) -> Laringoscopio | F6: 12366 | G6: =VLOOKUP(A6,Equipos!$A$2:$H$16545,4,FALSE) -> N/A
A7: BMO-TRMOH-00015064 | B7: 41942 | C7: 21/07/2022-NO_DEFINIDO - Solicitud de Servico Creada desde AMSi, 26/07/2022-Biomedico1 - Se realiza reemplazo de pantalla la cual se encontro partida se intala pantalla equipo funciona correctamente | D7: Pantalla | E7: =VLOOKUP(A7,Equipos!$1:$1048576,2,0) -> Termohigrometro Digital | F7: 15064 | G7: =VLOOKUP(A7,Equipos!$A$2:$H$16545,4,FALSE) -> N/A
A8: BDG-EQUIO-00007377 | B8: 41942 | C8: 01/08/2022-NO_DEFINIDO - Solicitud de Servico Creada desde AMSi, 02/08/2022-Biomedico1 - se realiza cambio de bombillo de equipo de órganos se realizan pruebas de funcionamiento equipo funciona correctamente | D8: Bombillo | E8: =VLOOKUP(A8,Equipos!$1:$1048576,2,0) -> Equipo De Organos Portatil | F8: 7377 | G8: =VLOOKUP(A8,Equipos!$A$2:$H$16545,4,FALSE) -> N/A
A9: BDG-EQUIO-00013803 | B9: 41942 | C9: 03/08/2022-NO_DEFINIDO - Solicitud de Servico Creada desde AMSi, 04/08/2022-Senior - Se cambia el bombillo del otoscopio del equipo de órganos, se realiza pruebas de funcionamiento y queda OK. | D9: Bombillo | E9: =VLOOKUP(A9,Equipos!$1:$1048576,2,0) -> Equipo Organos De Los Sentidos | F9: 13803 | G9: =VLOOKUP(A9,Equipos!$A$2:$H$16545,4,FALSE) -> N/A
A10: BDG-TENAT-00012867 | B10: 41942 | C10: 17/08/2022-NO_DEFINIDO - Solicitud de Servico Creada desde AMSi, 31/08/2022-Biomedico1 - Se realiza cambios de brazalete ya que presenta desgaste se realizan pruebas de funcionamiento equipo funciona correctamente | D10: Brazalete | E10: =VLOOKUP(A10,Equipos!$1:$1048576,2,0) -> Tensiometro De Atril | F10: 12867 | G10: =VLOOKUP(A10,Equipos!$A$2:$H$16545,4,FALSE) -> N/A
A11: OTP-CAMIL-00009406 | B11: 41942 | C11: 08/11/2022-NO_DEFINIDO - Solicitud de Servico Creada desde AMSi, 09/12/2022-Senior - Equipo se da de baja, ya que presenta deterioro en su estructura que no pudo ser reparada | D11: Baja | E11: =VLOOKUP(A11,Equipos!$1:$1048576,2,0) -> Camilla Fija-Divan | F11: 9406 | G11: =VLOOKUP(A11,Equipos!$A$2:$H$16545,4,FALSE) -> N/A
A12: OTP-CAMIL-00010629 | B12: 41942 | C12: 10/11/2022-NO_DEFINIDO - Solicitud de Servico Creada desde AMSi, 01/12/2022-Senior - Se realiza reemplazo de rueda por una de back up, pruebas de funcionamiento ok. Se adjunta reporte. | D12: Ruedas | E12: =VLOOKUP(A12,Equipos!$1:$1048576,2,0) -> Camilla De Transporte | F12: 10629 | G12: =VLOOKUP(A12,Equipos!$A$2:$H$16545,4,FALSE) -> N/A
A13: BDG-EQUIO-00016126 | B13: 41942 | C13: 30/11/2022-NO_DEFINIDO - Solicitud de Servico Creada desde AMSi, 25/01/2023-Senior - Se realiza ajuste en switch de encendido del equipo y se realiza el cambio de baterías | D13: Bateria | E13: =VLOOKUP(A13,Equipos!$1:$1048576,2,0) -> Equipo De Organos Portatil | F13: 16126/16127 | G13: =VLOOKUP(A13,Equipos!$A$2:$H$16545,4,FALSE) -> N/A
A14: OTP-CAMIL-00008945 | B14: 41942 | C14: 08/02/2023-NO_DEFINIDO - Solicitud de Servico Creada desde AMSi, 01/03/2023-Senior - Se realiza cambio de rueda. | D14: Ruedas | E14: =VLOOKUP(A14,Equipos!$1:$1048576,2,0) -> Camilla De Transporte | F14: 8945 | G14: =VLOOKUP(A14,Equipos!$A$2:$H$16545,4,FALSE) -> N/A
A15: BFE-LAMAU-00005914 | B15: 41942 | C15: 17/04/2023-NO_DEFINIDO - Solicitud de Servico Creada desde AMSi, 24/04/2023-Biomedico2 - Se realiza verificación de lámparas pieliticas, se realiza ajuste de soket y manilar ,se realiza cambio de bombillo, Se entrega sin novedad | D15: Bombillo | E15: =VLOOKUP(A15,Equipos!$1:$1048576,2,0) -> Lampara Auxiliar De Procedimientos | F15: 5914 | G15: =VLOOKUP(A15,Equipos!$A$2:$H$16545,4,FALSE) -> N/A
A16: BDG-TENPO-00005909 | B16: 41942 | C16: 10/01/2024-NO_DEFINIDO - Solicitud de Servico Creada desde AMSi, 11/01/2024-Biomedico1 - Se realiza ajuste de soporte de tensiómetro se realiza cambio de brazalete se realizan pruebas de funcionamiento equipo funciona correctamente | D16: Brazalete | E16: =VLOOKUP(A16,Equipos!$1:$1048576,2,0) -> Tensiometro Portatil | F16: 5909 | G16: =VLOOKUP(A16,Equipos!$A$2:$H$16545,4,FALSE) -> N/A
A17: BMO-TRMOH-00003811 | B17: 41942 | C17: 18/01/2024-NO_DEFINIDO - Solicitud de Servico Creada desde AMSi, 19/01/2024-Biomedico1 - Se realiza ajuste de conexión de batería se realizan pruebas equipo funciona correctamente | D17: Bateria | E17: =VLOOKUP(A17,Equipos!$1:$1048576,2,0) -> Termometro Digital | F17: 3811 | G17: =VLOOKUP(A17,Equipos!$A$2:$H$16545,4,FALSE) -> N/A
A18: BMO-TRMOH-00014155 | B18: 41942 | C18: 06/02/2024-NO_DEFINIDO - Solicitud de Servico Creada desde AMSi, 06/02/2024-Biomedico1 - Se realiza reemplazo de batería se evidencia leve aberturas en una esquina se realiza ajuste se realizan pruebas equipo funciona correctamente | D18: Bateria | E18: =VLOOKUP(A18,Equipos!$1:$1048576,2,0) -> Termohigrometro Digital | F18: 14155 | G18: =VLOOKUP(A18,Equipos!$A$2:$H$16545,4,FALSE) -> N/A
A19: BAN-LARIN-00015725 | B19: 41942 | C19: 26/02/2024-NO_DEFINIDO - Solicitud de Servico Creada desde AMSi, 10/03/2024-Biomedico2 - Se realiza cambio de bombillo por desgaste, se entrega sin novedad | D19: Bombillo | E19: =VLOOKUP(A19,Equipos!$1:$1048576,2,0) -> Laringoscopio | F19: 15725 | G19: =VLOOKUP(A19,Equipos!$A$2:$H$16545,4,FALSE) -> N/A
A20: BDG-EQUIO-00018895 | B20: 41942 | C20: 29/02/2024-NO_DEFINIDO - Solicitud de Servico Creada desde AMSi, 29/02/2024-Biomedico1 - Se realiza instalación de baterías nuevas equipo funciona correctamente | D20: Bateria | E20: =VLOOKUP(A20,Equipos!$1:$1048576,2,0) -> Equipo De Organos Portatil | F20: 18895/18896 | G20: =VLOOKUP(A20,Equipos!$A$2:$H$16545,4,FALSE) -> N/A
A21: BDG-BASME-00006049 | B21: 41942 | C21: 02/05/2024-NO_DEFINIDO - Solicitud de Servico Creada desde AMSi, 24/05/2024-Biomedico2 - Se realiza verificación con masas patrón y no se evidencia desajuste, se recomienda el cambio de las baterías | D21: Bateria | E21: =VLOOKUP(A21,Equipos!$1:$1048576,2,0) -> Bascula Mecanica | F21: 6049 | G21: =VLOOKUP(A21,Equipos!$A$2:$H$16545,4,FALSE) -> N/A
A22: BDG-TENAT-00012864 | B22: 41942 | C22: 06/05/2024-NO_DEFINIDO - Solicitud de Servico Creada desde AMSi, 29/05/2024-Biomedico2 - Se realiza ajustte de brazalete y regulador de pera ,se entrega sin novedad | D22: Brazalete | E22: =VLOOKUP(A22,Equipos!$1:$1048576,2,0) -> Tensiometro De Atril | F22: 12864 | G22: =VLOOKUP(A22,Equipos!$A$2:$H$16545,4,FALSE) -> N/A
A23: BAN-LARIN-00014221 | B23: 41942 | C23: 08/05/2024-NO_DEFINIDO - Solicitud de Servico Creada desde AMSi, 28/05/2024-Biomedico2 - Se realiza cambio de bombillo y se entrega sin novedad | D23: Bombillo | E23: =VLOOKUP(A23,Equipos!$1:$1048576,2,0) -> Laringoscopio | F23: 14221 | G23: =VLOOKUP(A23,Equipos!$A$2:$H$16545,4,FALSE) -> N/A
A24: BDG-EQUIO-00001076 | B24: 41942 | C24: 19/06/2024-NO_DEFINIDO - Solicitud de Servico Creada desde AMSi, 26/06/2024-Biomedico1 - Se retira equipo del servicio ya que llegó el equipo de reposición eeste equipo se encontraba en proceso de renovación y ya contaba con acta de baja | D24: Baja | E24: =VLOOKUP(A24,Equipos!$1:$1048576,2,0) -> Equipo Organos De Los Sentidos | F24: 1076 | G24: =VLOOKUP(A24,Equipos!$A$2:$H$16545,4,FALSE) -> N/A
A25: BAN-LARIN-00013920 | B25: 41942 | C25: 18/07/2024-NO_DEFINIDO - Solicitud de Servico Creada desde AMSi, 22/07/2024-Biomedico1 - Se realiza cambio de baterías de mango de laringo se realizan pruebas de funcionamiento equipo funciona correctamente | D25: Bateria | E25: =VLOOKUP(A25,Equipos!$1:$1048576,2,0) -> Laringoscopio | F25: 13920 | G25: =VLOOKUP(A25,Equipos!$A$2:$H$16545,4,FALSE) -> N/A
A26: BDG-TENAT-00012867 | B26: 41942 | C26: 29/08/2024-NO_DEFINIDO - Solicitud de Servico Creada desde AMSi, 03/09/2024-Biomedico1 - Se realiza cambio de brazalete de tensiómetro el cual se encuentra con desgaste se realizan prubas de funcionamiento equipo funciona correctamente | D26: Brazalete | E26: =VLOOKUP(A26,Equipos!$1:$1048576,2,0) -> Tensiometro De Atril | F26: 12867 | G26: =VLOOKUP(A26,Equipos!$A$2:$H$16545,4,FALSE) -> N/A
A27: BAN-LARIN-00015724 | B27: 41942 | C27: 01/09/2024-NO_DEFINIDO - Solicitud de Servico Creada desde AMSi, 07/10/2024-Biomedico2 - Se realiza verificación de mango de laringo y no se encuentra novedad, se realiza verificación de hojas de laringo y se evidencia bombillo suelto ,se realiza ajuste y se entrega sin novedad | D27: Bombillo | E27: =VLOOKUP(A27,Equipos!$1:$1048576,2,0) -> Laringoscopio | F27: 15724 | G27: =VLOOKUP(A27,Equipos!$A$2:$H$16545,4,FALSE) -> N/A
A28: BDG-TENAT-00012865 | B28: 41942 | C28: 05/09/2024-NO_DEFINIDO - Solicitud de Servico Creada desde AMSi, 10/09/2024-Biomedico1 - Se realiza cambio de brazalete y pers ya que presentan fuga se instala uno nuevo equipo funciona correctamente | D28: Brazalete | E28: =VLOOKUP(A28,Equipos!$1:$1048576,2,0) -> Tensiometro De Atril | F28: 12865 | G28: =VLOOKUP(A28,Equipos!$A$2:$H$16545,4,FALSE) -> N/A
A29: BAN-LARIN-00014222 | B29: 41942 | C29: 08/11/2024-NO_DEFINIDO - Solicitud de Servico Creada desde AMSi, 08/11/2024-Biomedico1 - Se realiza cambio de bombillo de laringoscopio ya que se encontraba fundido se instala uno nuevo se realizan pruebas equipo funciona correctamente | D29: Bombillo | E29: =VLOOKUP(A29,Equipos!$1:$1048576,2,0) -> Laringoscopio | F29: 14222 | G29: =VLOOKUP(A29,Equipos!$A$2:$H$16545,4,FALSE) -> N/A
A30: BAN-LARIN-00014221 | B30: 41942 | C30: 08/11/2024-NO_DEFINIDO - Solicitud de Servico Creada desde AMSi, 08/11/2024-Biomedico1 - Se realiza limpieza y cambio de baterías | D30: Bateria | E30: =VLOOKUP(A30,Equipos!$1:$1048576,2,0) -> Laringoscopio | F30: 14221 | G30: =VLOOKUP(A30,Equipos!$A$2:$H$16545,4,FALSE) -> N/A
A31: OTP-CAMIL-00009652 | B31: 41942 | C31: 26/12/2024-NO_DEFINIDO - Solicitud de Servico Creada desde AMSi, 24/01/2025-Senior - Faltaban cinturones y ruedas cristalizada, se instala una pareja de cinturón y se cambia una rueda por back up, debido a que se encontraba cristalizada, se recomienda cambio de ruedas. | D31: Ruedas | E31: =VLOOKUP(A31,Equipos!$1:$1048576,2,0) -> Camilla De Transporte | F31: 9652 | G31: =VLOOKUP(A31,Equipos!$A$2:$H$16545,4,FALSE) -> N/A
A32: BAN-LARIN-00012366 | B32: 41942 | C32: 27/01/2025-NO_DEFINIDO - Solicitud de Servico Creada desde AMSi, 29/01/2025-Biomedico1 - Se realiza verificación de mango d larin se realiza cambio de bombillo se realizan prubas de funcionamiento equipo funcionando correctamente | D32: Bombillo | E32: =VLOOKUP(A32,Equipos!$1:$1048576,2,0) -> Laringoscopio | F32: 12366 | G32: =VLOOKUP(A32,Equipos!$A$2:$H$16545,4,FALSE) -> N/A
... A63: BDG-EQUIO-00013153 | B63: 41942 | C63: -NO_DEFINIDO - Se realiza cambio de bombillo de oftalmoscopio. Equipo funciona correctamente. | D63: Bombillo | E63: =VLOOKUP(A63,Equipos!$1:$1048576,2,0) -> Equipo Organos De Los Sentidos | F63: 13153 | G63: =VLOOKUP(A63,Equipos!$A$2:$H$16545,4,FALSE) -> N/A
A64: BDG-EQUIO-00005986 | B64: 41942 | C64: -NO_DEFINIDO - Se realiza verificación inicial se realizan mediciones de voltaje en los puntos de conexión con los cabezales en el punto de conexión del otoscopio se evidencia que el voltaje no es el adecuado y mínimo requerido para que funcione el bombillo, se realiza inspección del punto de conexión de oftalmoscopio se evidencia que este se encuentra en las mininas condiciones, no cumple con el voltaje mínimo requerido para el funcionamiento del bombillo, se realiza inspección de la fuente en donde se evidencia componentes con fallas electrónicas, se realiza un testeo de la tarjeta y s evidencia afectación en gran parte de la tarjeta en la etapa de filtrado y regulación de voltaje de a tarjeta. Se realiza respectiva cotización de componentes pero estos no son comerciales por tal motivo se sugiere dar de baja el equipo ya que no es posible realizar la reparación. | D64: Bombillo | E64: =VLOOKUP(A64,Equipos!$1:$1048576,2,0) -> Equipo Organos De Los Sentidos | F64: 5986/10127 | G64: =VLOOKUP(A64,Equipos!$A$2:$H$16545,4,FALSE) -> N/A
A65: BAN-LARIN-00013553 | B65: 41942 | C65: -NO_DEFINIDO - Se realiza limpieza del mango de laringoscopio el cual se encontraba con abundante sulfatación en el socket, adicionalmente se realiza cambio a hoja de laringoscopio #3. Equipo funciona correctamente. | D65: Hoja de laringoscopio | E65: =VLOOKUP(A65,Equipos!$1:$1048576,2,0) -> Laringoscopio | F65: 13553 | G65: =VLOOKUP(A65,Equipos!$A$2:$H$16545,4,FALSE) -> N/A
A66: BAN-LARIN-00012077 | B66: 41942 | C66: -NO_DEFINIDO - e realiza cambio de bombillo se realizan pruebas de funcionamiento el equipo funciona correctamente | D66: Bombillo | E66: =VLOOKUP(A66,Equipos!$1:$1048576,2,0) -> Laringoscopio | F66: 12077 | G66: =VLOOKUP(A66,Equipos!$A$2:$H$16545,4,FALSE) -> N/A
A67: BAN-LARIN-00012075 | B67: 41942 | C67: -NO_DEFINIDO - Se realiza ajuste de bombillo de laringo. equipo queda funcionando correctamente | D67: Bombillo | E67: =VLOOKUP(A67,Equipos!$1:$1048576,2,0) -> Laringoscopio | F67: 12075 | G67: =VLOOKUP(A67,Equipos!$A$2:$H$16545,4,FALSE) -> N/A
A68: BDG-TENAT-00012867 | B68: 41942 | C68: -NO_DEFINIDO - Se realiza entrega de tensiómetro al servicio de consulta externa en perfectas condiciones de funcionamiento con brazalete nuevo y pera nueva.&#x0D; &#x0D; se adjunta reporte de entrega | D68: Brazalete | E68: =VLOOKUP(A68,Equipos!$1:$1048576,2,0) -> Tensiometro De Atril | F68: 12867 | G68: =VLOOKUP(A68,Equipos!$A$2:$H$16545,4,FALSE) -> N/A
A69: BAN-LARIN-00001387 | B69: 41942 | C69: -NO_DEFINIDO - Se realiza mantenimiento preventivo según cronograma.&#x0D; Se realiza revision del mango, bombillo, portabombillo, hojas de laringoscopio, verificacion de carga de las baterias, se entrega el equipo al servicio en funcionamiento, para su respectiva limpieza y desinfeccion. | D69: Bombillo | E69: =VLOOKUP(A69,Equipos!$1:$1048576,2,0) -> Laringoscopio | F69: 1387 | G69: =VLOOKUP(A69,Equipos!$A$2:$H$16545,4,FALSE) -> N/A
A70: BAN-LARIN-00006707 | B70: 41942 | C70: -NO_DEFINIDO - se realiza mantenimiento preventivo según cronograma&#x0D; Se realiza revision del mango, bombillo, portabombillo, hojas de laringoscopio, verificacion de carga de las baterias, se entrega el equipo al servicio en funcionamiento, para su respectiva limpieza y desinfeccion. | D70: Bombillo | E70: =VLOOKUP(A70,Equipos!$1:$1048576,2,0) -> Laringoscopio | F70: 6707 | G70: =VLOOKUP(A70,Equipos!$A$2:$H$16545,4,FALSE) -> N/A
...

Sheet Equipos
A1: Código AC | B1: Descripción | C1: Activo Fijo | D1: Serial | E1: Centro de Costo | F1: Marca | G1: Modelo | H1: Estado | I1: DIAS NO DISPO | K1: UBICACIÓN | L1: EQUIPO | M1: MARCA | N1: MODELO | O1: SERIE | P1: ACTIVO FIJO | Q1: FECHA DE ADQUISICION | R1: COSTO DE ADQUISICION | S1: EVALUACION ECONOMICA | V1: REMPLAZO | W1: TIEMPO DE FALLA
A2: BMO-MOSIV-00010553 | B2: Monitor De Signos Vitales | C2: 10553 | D2: CC22121790 | E2: Ginecologia | F2: Mindray | G2: Mec 1200 | H2: A - En Operación | I2: =VLOOKUP(C1,Datos!$F:$G,6,0) -> #REF! | S2: costo de mnto correctivo | T2: Costo Anual de mnto | U2: Subtotal de evaluación económica
A3: BMO-MOSIV-00000297 | B3: Monitor De Signos Vitales | C3: 297 | D3: AAW08310023SA | E3: QX Medicina General | F3: General Electric | G3: Procare 300 | H3: I - Dado de baja | I3: =VLOOKUP(C2,Datos!$F:$G,6,0) -> #REF! | K3: BANCO DE SANGRE | L3: AGITADOR DE PLAQUETAS | M3: HELMER | N3: PF15I | O3: 1017681 | P3: 13550 | Q3: 42195 | R3: 6237320 | S3: 458600 | T3: 870000 | U3: 4 | V3: No requiere renovación | W3: =VLOOKUP(P3,Datos!$F:$G,6,0) -> #REF!
A4: BMO-MOSIV-00009874 | B4: Monitor De Signos Vitales | C4: 9874 | D4: EX24001257 | E4: Urgencias Adulto | F4: Mindray | G4: Imec10 | H4: A - En Operación | I4: =VLOOKUP(C3,Datos!$F:$G,6,0) -> #REF! | K4: UNIDAD QUIRURGICA | L4: ARCO EN C | M4: SIEMENS | N4: SIREMOBIL | O4: 31192 | P4: 10109 | Q4: 41438 | R4: 325000000 | S4: 0 | T4: 16143000 | U4: 5 | V4: Evaluar tecnología en un año | W4: =VLOOKUP(P4,Datos!$F:$G,6,0) -> #REF!
A5: BEF-NEVER-00002694 | B5: Nevera | C5: 2694 | D5: 8012300602 | E5: Hospitalización | F5: Challenger | G5: Cr233 | H5: I - Dado de Baja | I5: =VLOOKUP(C4,Datos!$F:$G,6,0) -> #REF! | K5: UNIDAD QUIRURGICA | L5: ARCO EN C | M5: SIEMENS | N5: SIREMOBIL COMPACT L | O5: 9857-4429 | P5: 265 | Q5: 39560 | R5: 165297251 | S5: 2050000 | T5: 15838000 | U5: 4 | V5: Reemplazo inmmediato | W5: =VLOOKUP(P5,Datos!$F:$G,6,0) -> #REF!
A6: BMO-MONFE-00007841 | B6: Monitor Fetal | C6: 7841 | D6: SAS10024555PA | E6: Ginecologia | F6: General Electric | G6: Corometrics 170 | H6: A - En Operación | I6: =VLOOKUP(C5,Datos!$F:$G,6,0) -> #REF! | K6: UNIDAD QUIRURGICA | L6: ARCO EN C | M6: SIEMENS | N6: CIOS SELECT | O6: 12793 | P6: 16700 | Q6: 44146 | R6: 213006671 | S6: 0 | T6: 19250000 | U6: 4 | V6: No requiere renovación | W6: =VLOOKUP(P6,Datos!$F:$G,6,0) -> #REF!
A7: BLP-FUENL-00010233 | B7: Fuente de Luz (Torre Wolf) | C7: 10233 | D7: 1100151942 | E7: Salas De Cirugia | F7: Richard Wolf | G7: 5132002 | H7: A - En Operación | I7: =VLOOKUP(C6,Datos!$F:$G,6,0) -> #REF! | K7: CONSULTA EXTERNA | L7: AUDIOMETRO | M7: MAICO | N7: MA42 | O7: 23322 | P7: 13008 | Q7: 39855 | R7: 15000000 | S7: 0 | T7: 946050 | U7: 5 | V7: Funcionamiento aprox 1 año | W7: =VLOOKUP(P7,Datos!$F:$G,6,0) -> #REF!
A8: BMP-MESAC-00015729 | B8: Mesa De Procedimientos Quirurgicos | C8: 15729 | D8: G9-94007284 | E8: Salas De Cirugia | F8: Mindray | G8: Hybase 6100 | H8: A - En Operación | I8: =VLOOKUP(C7,Datos!$F:$G,6,0) -> #REF! | K8: TERAPIA FISICA | L8: BANDA TROTADORA | M8: SPORTFITNESS | N8: NIMES | O8: B170520029 | P8: 15249 | Q8: 43181 | R8: 6637750 | S8: 110000 | T8: 600000 | U8: 4 | V8: No requiere renovación | W8: =VLOOKUP(P8,Datos!$F:$G,6,0) -> #REF!
A9: BMO-MONFE-00007841 | B9: Monitor Fetal | C9: 7841 | D9: SAS10024555PA | E9: Ginecologia | F9: General Electric | G9: Corometrics 170 | H9: A - En Operación | I9: =VLOOKUP(C8,Datos!$F:$G,6,0) -> #REF! | K9: TERAPIA FISICA | L9: BANDA TROTADORA | M9: SPORTFITNESS | N9: NIMES | O9: B170820030 | P9: 15250 | Q9: 43181 | R9: 6637750 | S9: 0 | T9: 600000 | U9: 5 | V9: No requiere renovación | W9: =VLOOKUP(P9,Datos!$F:$G,6,0) -> #REF!
A10: BDG-MOSIV-00117728 | B10: Monitor De Signos Vitales | C10: Alquiler | D10: 117728 | E10: Biomedica | F10: Nihon kohden | G10: PVM-2701 | H10: A - En Operación | I10: =VLOOKUP(C9,Datos!$F:$G,6,0) -> #REF! | K10: UNIDAD QUIRURGICA | L10: BAÑO SEROLOGICO | M10: MEMMERT | N10: WNE 10 | O10: 13080690 | P10: 7526 | Q10: 40305 | R10: 3405099 | S10: 0 | T10: 600000 | U10: 4 | V10: Evaluar tecnología en un año | W10: =VLOOKUP(P10,Datos!$F:$G,6,0) -> #REF!
A11: BDG-MOSIV-00117728 | B11: Monitor De Signos Vitales | C11: Alquiler | D11: 117728 | E11: Biomedica | F11: Nihon kohden | G11: PVM-2701 | H11: A - En Operación | I11: =VLOOKUP(C10,Datos!$F:$G,6,0) -> #REF! | K11: BIOMEDICA | L11: BAÑO SEROLOGICO | M11: MEMMERT | N11: W270 | O11: 800890 | P11: 5644 | Q11: 38930 | R11: 1000000 | S11: 0 | T11: 600000 | U11: 2 | V11: Funcionamiento aprox 1 año | W11: =VLOOKUP(P11,Datos!$F:$G,6,0) -> #REF!
A12: BDG-MOSIV-00117728 | B12: Monitor De Signos Vitales | C12: Alquiler | D12: 117728 | E12: Biomedica | F12: Nihon kohden | G12: PVM-2701 | H12: A - En Operación | I12: =VLOOKUP(C11,Datos!$F:$G,6,0) -> #REF! | K12: HOSPITALIZACION | L12: BASCULA DIGITAL | M12: KENWELL | N12: EB9003 | O12: 5348 | P12: 15753 | Q12: 43676 | R12: 275842 | S12: 0 | T12: 600000 | U12: FALSE | V12: No requiere renovación | W12: =VLOOKUP(P12,Datos!$F:$G,6,0) -> #REF!
A13: BID-ARCON-00000265 | B13: Arco en C | C13: 265 | D13: 4429 | E13: Salas De Cirugia | F13: Siemens | G13: Multimobil Compact 1 | H13: A - En Operación | I13: =VLOOKUP(C12,Datos!$F:$G,6,0) -> #REF! | K13: BANCO DE SANGRE | L13: BASCULA DIGITAL | M13: AND | N13: SK100 | O13: h6081039 | P13: 5621 | Q13: 38930 | R13: 500000 | S13: 0 | T13: 600000 | U13: FALSE | V13: Funcionamiento aprox 1 año | W13: =VLOOKUP(P13,Datos!$F:$G,6,0) -> #REF!
A14: BDG-BASTA-00007156 | B14: Bascula Con Tallimetro | C14: 19426 | D14: N/A | E14: Consulta Externa | F14: Health O Meter | G14: 220 KG | H14: A - En Operación | I14: =VLOOKUP(C13,Datos!$F:$G,6,0) -> #REF! | K14: BANCO DE SANGRE | L14: BASCULA DIGITAL | M14: AND | N14: SK100 | O14: H6081051 | P14: 5620 | Q14: 38930 | R14: 500000 | S14: 0 | T14: 600000 | U14: FALSE | V14: Funcionamiento aprox 1 año | W14: =VLOOKUP(P14,Datos!$F:$G,6,0) -> #REF!
A15: BMO-MONFE-00007841 | B15: Monitor Fetal | C15: 7841 | D15: SAS10024555PA | E15: Ginecologia | F15: General Electric | G15: Corometrics 170 | H15: A - En Operación | I15: =VLOOKUP(C14,Datos!$F:$G,6,0) -> #REF! | K15: CENTRO MEDICO | L15: BASCULA DIGITAL | M15: SECA | N15: 874DR | O15: 10000000293657 | P15: 16863 | Q15: 44293 | R15: 1925518 | S15: 0 | T15: 600000 | U15: 4 | V15: No requiere renovación | W15: =VLOOKUP(P15,Datos!$F:$G,6,0) -> #REF!
A16: BEF-NEVER-00006630 | B16: Nevera | C16: 6630 | D16: 080123-00602 | E16: Urgencias Adulto | F16: Challenger | G16: Arezzo | H16: I - Dado de baja | I16: =VLOOKUP(C15,Datos!$F:$G,6,0) -> #REF! | K16: NUTRICIÓN | L16: BASCULA DIGITAL | M16: SECA | N16: 874DR | O16: 10000000371735 | P16: 17795 | Q16: 44533 | R16: 1925518 | S16: 0 | T16: 400000 | U16: 4 | V16: No requiere renovación | W16: =VLOOKUP(P16,Datos!$F:$G,6,0) -> #REF!
A17: BMO-MOSIV-00009874 | B17: Monitor De Signos Vitales | C17: 9874 | D17: EX24001257 | E17: Urgencias Adulto | F17: Mindray | G17: Imec10 | H17: A - En Operación | I17: =VLOOKUP(C16,Datos!$F:$G,6,0) -> #REF! | K17: CONSULTA EXTERNA | L17: BASCULA DIGITAL | M17: SECA | N17: 813 | O17: 8813038202248 | P17: 16809 | Q17: 44237 | R17: 842520 | S17: 0 | T17: 600000 | U17: 2 | V17: No requiere renovación | W17: =VLOOKUP(P17,Datos!$F:$G,6,0) -> #REF!
A18: BMO-MOSIV-00015789 | B18: Monitor De Signos Vitales | C18: 15789 | D18: KN-94041489 | E18: Salas De Cirugia | F18: Mindray | G18: uMEC 10 | H18: A - En Operación | I18: =VLOOKUP(C17,Datos!$F:$G,6,0) -> #REF! | K18: URGENCIAS | L18: BASCULA DIGITAL | M18: HEALTH O METER | N18: 880KL | O18: 88042210000017 | P18: 18237 | Q18: 44813 | R18: 492443 | S18: 0 | T18: 600000 | U18: FALSE | V18: Evaluar tecnología en un año | W18: =VLOOKUP(P18,Datos!$F:$G,6,0) -> #REF!
A19: BMO-MOSIV-00010013 | B19: Monitor De Signos Vitales | C19: 10013 | D19: CC28123455 | E19: Ginecologia | F19: Mindray | G19: Mec1200 | H19: A - En Operación | I19: =VLOOKUP(C18,Datos!$F:$G,6,0) -> #REF! | K19: CONSULTA EXTERNA | L19: BASCULA DIGITAL | M19: SECA | N19: 813 | O19: 8813038201992 | P19: 16830 | Q19: 44235 | R19: 842520 | S19: 0 | T19: 600000 | U19: 2 | V19: No requiere renovación | W19: =VLOOKUP(P19,Datos!$F:$G,6,0) -> #REF!
A20: BMO-MOSIV-00008129 | B20: Monitor De Signos Vitales | C20: 8129 | D20: AA11134646 | E20: Hospitalización | F20: Mindray | G20: Pm8000 | H20: A - En Operación | I20: =VLOOKUP(C19,Datos!$F:$G,6,0) -> #REF! | K20: CUARTO DE RESIDUOS | L20: BASCULA ELECTRONICA INDUSTRIAL | M20: BBG | N20: R5232 | O20: 12E161231004 | P20: 14348 | Q20: 42795 | R20: 1500000 | S20: 0 | T20: 600000 | U20: 3 | V20: No requiere renovación | W20: =VLOOKUP(P20,Datos!$F:$G,6,0) -> #REF!
A21: BMO-MOSIV-00008129 | B21: Monitor De Signos Vitales | C21: 8129 | D21: AA11134646 | E21: Hospitalización | F21: Mindray | G21: Pm8000 | H21: A - En Operación | I21: =VLOOKUP(C20,Datos!$F:$G,6,0) -> #REF! | K21: CUARTO DE RESIDUOS | L21: BASCULA ELECTRONICA INDUSTRIAL | M21: BBG | N21: INDUSTRY20 | O21: 12E181227104 | P21: 16105 | Q21: 44063 | R21: 1500000 | S21: 0 | T21: 600000 | U21: 3 | V21: No requiere renovación | W21: =VLOOKUP(P21,Datos!$F:$G,6,0) -> #REF!
A22: BMO-MOSIV-00000294 | B22: Monitor De Signos Vitales | C22: 294 | D22: AAW07240072SA | E22: Biomedica | F22: General Electric | G22: Procare 300 | H22: I - Dado de baja | I22: =VLOOKUP(C21,Datos!$F:$G,6,0) -> #REF! | K22: URGENCIAS ADULTOS | L22: BASCULA MECANICA | M22: NEWMED | N22: DT05 | O22: BANM2015749 | P22: 14293 | Q22: 42769 | R22: 174000 | S22: 0 | T22: 600000 | U22: FALSE | V22: No requiere renovación | W22: =VLOOKUP(P22,Datos!$F:$G,6,0) -> #REF!
A23: BMO-MOSIV-00014803 | B23: Monitor De Signos Vitales | C23: 14803 | D23: KN73006796 | E23: Ginecologia | F23: Mindray | G23: Umec 10 | H23: A - En Operación | I23: =VLOOKUP(C22,Datos!$F:$G,6,0) -> #REF! | K23: URGENCIAS PEDIATRIA | L23: BASCULA CON TALLIMETRO | M23: DETECTO | N23: 200KG | O23: SIN | P23: 7507 | Q23: 39778 | R23: 794600 | S23: 0 | T23: 600000 | U23: 2 | V23: Funcionamiento aprox 1 año | W23: =VLOOKUP(P23,Datos!$F:$G,6,0) -> #REF!
A24: B | B24: #N/A | C24: #N/A | D24: #N/A | E24: #N/A | F24: #N/A | G24: #N/A | H24: #N/A | I24: =VLOOKUP(C23,Datos!$F:$G,6,0) -> #REF! | K24: URGENCIAS PEDIATRIA | L24: BASCULA CON TALLIMETRO | M24: HEALTH O METER | N24: 200KG | O24: SIN | P24: 9742/17108 | Q24: 40304 | R24: 174000 | S24: 0 | T24: 600000 | U24: FALSE | V24: Funcionamiento aprox 1 año | W24: =VLOOKUP(P24,Datos!$F:$G,6,0) -> #REF!
A25: BMO-MOSIV-00013491 | B25: Monitor De Signos Vitales | C25: 13491 | D25: CC53131303 | E25: Salas De Cirugia | F25: Mindray | G25: Mec 1200 | H25: A - En Operación | I25: =VLOOKUP(C24,Datos!$F:$G,6,0) -> #N/A | K25: URGENCIAS ADULTOS | L25: BASCULA CON TALLIMETRO | M25: DETECTO | N25: 200KG | O25: 173140090076 | P25: 14292 | Q25: 42769 | R25: 457272 | S25: 0 | T25: 600000 | U25: FALSE | V25: No requiere renovación | W25: =VLOOKUP(P25,Datos!$F:$G,6,0) -> #REF!
A26: BMO-MOSIV-00010013 | B26: Monitor De Signos Vitales | C26: 10013 | D26: CC28123455 | E26: Ginecologia | F26: Mindray | G26: Mec1200 | H26: A - En Operación | I26: =VLOOKUP(C25,Datos!$F:$G,6,0) -> #REF! | K26: CONSULTA EXTERNA | L26: BASCULA CON TALLIMETRO | M26: DETECTO | N26: 220KG | O26: SIN | P26: 13704 | Q26: 42319 | R26: 457272 | S26: 0 | T26: 600000 | U26: FALSE | V26: Evaluar tecnología en un año | W26: =VLOOKUP(P26,Datos!$F:$G,6,0) -> #REF!
A27: BMO-MONFE-00007841 | B27: Monitor Fetal | C27: 7841 | D27: SAS10024555PA | E27: Ginecologia | F27: General Electric | G27: Corometrics 170 | H27: A - En Operación | I27: =VLOOKUP(C26,Datos!$F:$G,6,0) -> #REF! | K27: CONSULTA EXTERNA | L27: BASCULA CON TALLIMETRO | M27: SECA | N27: 220KG | O27: SIN | P27: 13245 | Q27: 42122 | R27: 1469720 | S27: 0 | T27: 600000 | U27: 3 | V27: Evaluar tecnología en un año | W27: =VLOOKUP(P27,Datos!$F:$G,6,0) -> #REF!
A28: B | B28: #N/A | C28: #N/A | D28: #N/A | E28: #N/A | F28: #N/A | G28: #N/A | H28: #N/A | I28: =VLOOKUP(C27,Datos!$F:$G,6,0) -> #REF! | K28: CONSULTA EXTERNA | L28: BASCULA CON TALLIMETRO | M28: WELCH ALLYN | N28: 402KL | O28: 402WA03066 | P28: 12878 | Q28: 41982 | R28: 533600 | S28: 0 | T28: 600000 | U28: FALSE | V28: Evaluar tecnología en un año | W28: =VLOOKUP(P28,Datos!$F:$G,6,0) -> #REF!
A29: BMO-MOSIV-00015588 | B29: Monitor De Signos Vitales | C29: 15588 | D29: 6009532669 | E29: Salas De Cirugia | F29: Drager | G29: Infinity Del | H29: A - En Operación | I29: =VLOOKUP(C28,Datos!$F:$G,6,0) -> #N/A | K29: HOSPITALIZACION | L29: BASCULA CON TALLIMETRO | M29: DETECTO | N29: 125KG | O29: SIN | P29: 8079 | Q29: 38930 | R29: 500000 | S29: 0 | T29: 600000 | U29: FALSE | V29: Funcionamiento aprox 1 año | W29: =VLOOKUP(P29,Datos!$F:$G,6,0) -> #REF!
A30: BMO-MOSIV-00015467 | B30: Monitor De Signos Vitales | C30: 15467 | D30: 6009570075 | E30: Salas De Cirugia | F30: Drager | G30: Infinity Del | H30: A - En Operación | I30: =VLOOKUP(C29,Datos!$F:$G,6,0) -> #REF! | K30: CONSULTA EXTERNA | L30: BASCULA CON TALLIMETRO | M30: HEALTH O METER | N30: 220KG | O30: SIN | P30: 7156 | Q30: 38930 | R30: 600000 | S30: 0 | T30: 600000 | U30: 1 | V30: Funcionamiento aprox 1 año | W30: =VLOOKUP(P30,Datos!$F:$G,6,0) -> #REF!
A31: BCC-ELCBI-00015082 | B31: Electrobisturi | C31: 15082 | D31: S7F26607AX | E31: Salas De Cirugia | F31: Valleylab | G31: Force Fx-C | H31: A - En Operación | I31: =VLOOKUP(C30,Datos!$F:$G,6,0) -> #REF! | K31: CONSULTA EXTERNA | L31: BASCULA CON TALLIMETRO | M31: HEALTH O METER | N31: 1160 KG | O31: SIN | P31: 6143 | Q31: 39780 | R31: 794600 | S31: 0 | T31: 600000 | U31: 2 | V31: Evaluar tecnología en un año | W31: =VLOOKUP(P31,Datos!$F:$G,6,0) -> #REF!
A32: BMO-MOSIV-00005329 | B32: Monitor De Signos Vitales | C32: 5329 | D32: CE8B110447 | E32: Salas De Cirugia | F32: Mindray | G32: Pm7000 | H32: I - Dado de baja | I32: =VLOOKUP(C31,Datos!$F:$G,6,0) -> #REF! | K32: CONSULTA EXTERNA | L32: BASCULA CON TALLIMETRO | M32: DETECTO | N32: SIN | O32: SIN | P32: 5941 | Q32: 38930 | R32: 500000 | S32: 0 | T32: 600000 | U32: FALSE | V32: Funcionamiento aprox 1 año | W32: =VLOOKUP(P32,Datos!$F:$G,6,0) -> #REF!
A33: BMO-MOSIV-00010048 | B33: Monitor De Signos Vitales | C33: 10048 | D33: EX-31004634 | E33: Salas De Cirugia | F33: Mindray | G33: Imec10 | H33: I - Dado de baja | I33: =VLOOKUP(C32,Datos!$F:$G,6,0) -> #REF! | K33: CONSULTA EXTERNA | L33: BASCULA CON TALLIMETRO | M33: DETECTO | N33: 220KG | O33: 1731410090316 | P33: 14289 | Q33: 42769 | R33: 547000 | S33: 0 | T33: 600000 | U33: FALSE | V33: No requiere renovación | W33: =VLOOKUP(P33,Datos!$F:$G,6,0) -> #REF!
A34: BMO-MOSIV-00010013 | B34: Monitor De Signos Vitales | C34: 10013 | D34: CC28123455 | E34: Ginecologia | F34: Mindray | G34: Mec1200 | H34: A - En Operación | I34: =VLOOKUP(C33,Datos!$F:$G,6,0) -> #REF! | K34: CONSULTA EXTERNA | L34: BASCULA CON TALLIMETRO | M34: DETECTO | N34: 220KG | O34: 1731410090313 | P34: 14290 | Q34: 42769 | R34: 547000 | S34: 0 | T34: 600000 | U34: FALSE | V34: No requiere renovación | W34: =VLOOKUP(P34,Datos!$F:$G,6,0) -> #REF!
A35: B | B35: #N/A | C35: #N/A | D35: #N/A | E35: #N/A | F35: #N/A | G35: #N/A | H35: #N/A | I35: =VLOOKUP(C34,Datos!$F:$G,6,0) -> #REF! | K35: CONSULTA EXTERNA | L35: BASCULA CON TALLIMETRO | M35: HEALTH O METER | N35: 450kL | O35: 4500015992 | P35: 15752 | Q35: 43676 | R35: 1206284 | S35: 0 | T35: 600000 | U35: 3 | V35: No requiere renovación | W35: =VLOOKUP(P35,Datos!$F:$G,6,0) -> #REF!
A36: BMO-MOSIV-00000285 | B36: Monitor De Signos Vitales | C36: 285 | D36: AA93114424 | E36: Salas De Cirugia | F36: Mindray | G36: Pm8000 | H36: A - En Operación | I36: =VLOOKUP(C35,Datos!$F:$G,6,0) -> #N/A | K36: CENTRO MEDICO | L36: BASCULA CON TALLIMETRO | M36: BBG | N36: PP-150 | O36: 20015040300 | P36: 15302 | Q36: 43266 | R36: 875840 | S36: 0 | T36: 600000 | U36: 2 | V36: No requiere renovación | W36: =VLOOKUP(P36,Datos!$F:$G,6,0) -> #REF!
A37: BFE-LAMPI-00000067 | B37: Lampara Pielitica Auxiliar De Cirugia | C37: 67 | D37: E031-G1-0002 | E37: Ginecologia | F37: Trident Medical | G37: Domelux6200s | H37: A - En Operación | I37: =VLOOKUP(C36,Datos!$F:$G,6,0) -> #REF! | K37: CONSULTA EXTERNA | L37: BASCULA CON TALLIMETRO | M37: HEALTH O METER | N37: 160 KG | O37: SIN SERIE | P37: 6111/12760 | Q37: 38930 | R37: 500000 | S37: 0 | T37: 600000 | U37: FALSE | V37: Funcionamiento aprox 1 año | W37: =VLOOKUP(P37,Datos!$F:$G,6,0) -> #REF!
A38: B | B38: #N/A | C38: #N/A | D38: #N/A | E38: #N/A | F38: #N/A | G38: #N/A | H38: #N/A | I38: =VLOOKUP(C37,Datos!$F:$G,6,0) -> #REF! | K38: URGENCIAS ADULTOS | L38: BASCULA CON TALLIMETRO | M38: HEALTH O METER | N38: 140KG | O38: SIN SERIE | P38: 1066 | Q38: 38930 | R38: 500000 | S38: 0 | T38: 600000 | U38: FALSE | V38: Reemplazo inmmediato | W38: =VLOOKUP(P38,Datos!$F:$G,6,0) -> #REF!
A39: BMO-MONFE-00007841 | B39: Monitor Fetal | C39: 7841 | D39: SAS10024555PA | E39: Ginecologia | F39: General Electric | G39: Corometrics 170 | H39: A - En Operación | I39: =VLOOKUP(C38,Datos!$F:$G,6,0) -> #N/A | K39: CENTRO MEDICO | L39: BASCULA CON TALLIMETRO | M39: HEALTH O METER | N39: 142KL | O39: 1420078451 | P39: 15747 | Q39: 43669 | R39: 154700 | S39: 0 | T39: 600000 | U39: FALSE | V39: No requiere renovación | W39: =VLOOKUP(P39,Datos!$F:$G,6,0) -> #REF!
A40: BMO-MOSIV-00014800 | B40: Monitor De Signos Vitales | C40: 14800 | D40: KN73006799 | E40: Hospitalización | F40: Mindray | G40: Umec 10 | H40: A - En Operación | I40: =VLOOKUP(C39,Datos!$F:$G,6,0) -> #REF! | K40: CONSULTA EXTERNA | L40: BASCULA CON TALLIMETRO | M40: SECA | N40: 777 | O40: 10000000305725 | P40: 16901 | Q40: 44286 | R40: 2474010 | S40: 0 | T40: 600000 | U40: 4 | V40: No requiere renovación | W40: =VLOOKUP(P40,Datos!$F:$G,6,0) -> #REF!
...

Sheet Ingreso
A1: FECHA INGRESO SERVINTE | B1: CODIGO SERVINTE | C1: DESCRIPCIÓN | D1: DESCRIPCION DETALLADA | E1: PROPIETARIO | F1: MARCA | G1: MODELO | H1: SERIE | I1: PLACA HIUSJ
A2: 41942 | B2: D13334 | C2: ARCO EN C | D2: INTENSIFICADOR DE IMÁGENES | E2: SIN IDENTIFICAR | F2: SIREMOBIL COMPACT | G2: SIEMENS | H2: 9857- 4429 | I2: 265
A3: 41942 | B3: D16234 | C3: TERMOHIGROMETRO DIGITAL | D3: TERMOMETRO HIGROMETRO DIGITAL | E3: SIN IDENTIFICAR | F3: 1452 | G3: TAYLOR | H3: SIN SERIE | I3: 5631
A4: 41942 | B4: D16235 | C4: TERMOHIGROMETRO DIGITAL | D4: TERMOMETRO HIGROMETRO DIGITAL | E4: SIN IDENTIFICAR | F4: SH109 | G4: KEX GERMANY | H4: SIN SERIE | I4: 11326
A5: 41942 | B5: D16236 | C5: TERMOHIGROMETRO DIGITAL | D5: TERMOMETRO HIGROMETRO DIGITAL | E5: SIN IDENTIFICAR | F5: SH109 | G5: KEX GERMANY | H5: SIN SERIE | I5: 9054
A6: 41942 | B6: D16242 | C6: TERMOHIGROMETRO DIGITAL | D6: TERMO HIGRONOMETRO | E6: SIN IDENTIFICAR | F6: SH-109 | G6: KEX GERMANY | H6: SIN SERIE | I6: 11665
A7: 41942 | B7: D16243 | C7: TERMOHIGROMETRO DIGITAL | D7: TERMOHIGROMETRO | E7: SIN IDENTIFICAR | F7: 3209V0270 | G7: TAYLOR | H7: 1423 | I7: 11862
A8: 41942 | B8: D16727 | C8: MONITOR DE SIGNOS VITALES | D8: MONITOR DE SIGNOS VITALES | E8: SIN IDENTIFICAR | F8: CARDIOCAP | G8: DATEX HOMEDA | H8: 6305699 | I8: 504
A9: 41942 | B9: D16630 | C9: GLUCOMETRO FREESTYLE OPTIUM NEO H ( CON ESTUCHE) | D9: MEDIDOR DE GLUCOSA | E9: COMODATO | F9: NEO H | G9: FREESTYLE | H9: LBGU198F12011 | I9: COMODATO
A10: 41942 | B10: D16631 | C10: GLUCOMETRO FREESTYLE OPTIUM NEO H ( CON ESTUCHE) | D10: MEDIDOR DE GLUCOSA | E10: COMODATO | F10: NEO H | G10: FREESTYLE | H10: LBGV160S04741 | I10: COMODATO
A11: 41942 | B11: D16632 | C11: GLUCOMETRO FREESTYLE OPTIUM NEO H ( CON ESTUCHE) | D11: MEDIDOR DE GLUCOSA | E11: COMODATO | F11: NEO H | G11: FREESTYLE | H11: LBGV160S01836 | I11: COMODATO
A12: 41942 | B12: D16633 | C12: GLUCOMETRO FREESTYLE OPTIUM NEO H ( CON ESTUCHE) | D12: MEDIDOR DE GLUCOSA | E12: COMODATO | F12: NEO H | G12: FREESTYLE | H12: LBGV160S03485 | I12: COMODATO
A13: 41942 | B13: D16634 | C13: GLUCOMETRO FREESTYLE OPTIUM NEO H ( CON ESTUCHE) | D13: MEDIDOR DE GLUCOSA | E13: COMODATO | F13: NEO H | G13: FREESTYLE | H13: LBGV120S01912 | I13: COMODATO
A14: 41942 | B14: D16635 | C14: GLUCOMETRO FREESTYLE OPTIUM NEO H ( CON ESTUCHE) | D14: MEDIDOR DE GLUCOSA | E14: COMODATO | F14: NEO H | G14: FREESTYLE | H14: LBGV160S03167 | I14: COMODATO
A15: 41942 | B15: D16636 | C15: GLUCOMETRO FREESTYLE OPTIUM NEO H ( CON ESTUCHE) | D15: MEDIDOR DE GLUCOSA | E15: COMODATO | F15: NEO H | G15: FREESTYLE | H15: LBGV160S01811 | I15: COMODATO
A16: 41942 | B16: D16637 | C16: GLUCOMETRO FREESTYLE OPTIUM NEO H ( CON ESTUCHE) | D16: MEDIDOR DE GLUCOSA | E16: COMODATO | F16: NEO H | G16: FREESTYLE | H16: LBGV160S03097 | I16: COMODATO
A17: 41942 | B17: D16638 | C17: GLUCOMETRO FREESTYLE OPTIUM NEO H ( CON ESTUCHE) | D17: MEDIDOR DE GLUCOSA | E17: COMODATO | F17: NEO H | G17: FREESTYLE | H17: LBGU319F09464 | I17: COMODATO
A18: 41942 | B18: D16639 | C18: GLUCOMETRO FREESTYLE OPTIUM NEO H ( CON ESTUCHE) | D18: MEDIDOR DE GLUCOSA | E18: COMODATO | F18: NEO H | G18: FREESTYLE | H18: LBGV160S01811 | I18: COMODATO
A19: 41942 | B19: D16642 | C19: GLUCOMETRO FREESTYLE OPTIUM NEO H ( CON ESTUCHE) | D19: MEDIDOR DE GLUCOSA | E19: COMODATO | F19: NEO H | G19: FREESTYLE | H19: LBGU198F12011 | I19: COMODATO
A20: 41942 | B20: D16643 | C20: GLUCOMETRO FREESTYLE OPTIUM NEO H ( CON ESTUCHE) | D20: MEDIDOR DE GLUCOSA | E20: COMODATO | F20: NEO H | G20: FREESTYLE | H20: LBGV160S04741 | I20: COMODATO
A21: 41942 | B21: D10134 | C21: MAQUINA DE ANESTESIA | D21: MAQUINA DE ANESTESIA | E21: HOSPITAL | F21: AESTIVA/5 MRI | G21: GE | H21: AMTR-500247 | I21: 9931
A22: 41942 | B22: D13343 | C22: SUCCIONADOR PORTATIL | D22: SUCCIONADOR | E22: HOSPITAL | F22: 1630 | G22: THOMAS | H22: 10900002151 | I22: 7512
A23: 41942 | B23: D13344 | C23: SUCCIONADOR PORTATIL | D23: ASPIRADOR PORTATIL REF 1630 THOMAS | E23: HOSPITAL | F23: 1630 | G23: THOMAS | H23: 81100007270 | I23: 10020-15773
A24: 41942 | B24: D13346 | C24: SUCCIONADOR PORTATIL | D24: SUCCIONADOR | E24: HOSPITAL | F24: 1630-BEJL06449 | G24: THOMAS | H24: 010900002152 | I24: 15775
A25: 41942 | B25: D13373 | C25: PESA BEBE | D25: PESA BEBE | E25: HOSPITAL | F25: 1522KL | G25: HEALTH A METER | H25: 1522010830 | I25: 11866
A26: 41942 | B26: D13376 | C26: BANDEJA PORTA DIFUNTO | D26: BANDEJA METALICA PARA CADAVERES | E26: HOSPITAL | F26: SIN MODELO | G26: SIN MARCA | H26: SIN SERIE | I26: 0
A27: 41942 | B27: D13377 | C27: BANDEJA PORTA DIFUNTO | D27: BANDEJA METALICA PARA CADAVERES | E27: HOSPITAL | F27: SIN MODELO | G27: SIN MARCA | H27: SIN SERIE | I27: 9999
A28: 41942 | B28: D13381 | C28: BASCULA MECANICA | D28: BASCULA PESA BEBE | E28: HOSPITAL | F28: 70 KL | G28: HEALTH A METER | H28: 483418 | I28: 7520
A29: 41942 | B29: D13396 | C29: BASCULA MECANICA | D29: PESA BEBE DIGITAL | E29: HOSPITAL | F29: MECANICA | G29: SIN MARCA | H29: SIN SERIE | I29: 108
A30: 41942 | B30: D13400 | C30: BASCULA TALLIMETRO | D30: BASCULA TALLIMETRO | E30: HOSPITAL | F30: SIN MODELO | G30: DETECTO | H30: SIN SERIE | I30: 9742
A31: 41942 | B31: D13413 | C31: TALLIMETRO EN ACRILICO | D31: TALLIMETRO EN ACRILICO | E31: HOSPITAL | F31: SIN MODELO | G31: SIN MARCA | H31: SIN SERIE | I31: 9572
A32: 41942 | B32: D13418 | C32: BASCULA TALLIMETRO | D32: PESA TALLIMETRO | E32: HOSPITAL | F32: 200 KG | G32: DETECTO | H32: SIN SERIE | I32: 7507
A33: 41942 | B33: D13465 | C33: CAMPANA ACOPLE DUCTO | D33: CAMPANA ACOPLE DUCTO | E33: HOSPITAL | F33: SIN MODELO | G33: SIN MARCA | H33: SIN SERIE | I33: 0
A34: 41942 | B34: D13466 | C34: CAMPANA CENTRAL | D34: CAMPANA CENTRAL | E34: HOSPITAL | F34: SIN MODELO | G34: SIN MARCA | H34: SIN SERIE | I34: 0
A35: 41942 | B35: D13514 | C35: CAPNOGRAFO MONITOR EMMA CON AL | D35: CAPNOGRAFO | E35: HOSPITAL | F35: ETCO | G35: EMMA | H35: 605102 | I35: 9896
A36: 41942 | B36: D13515 | C36: CAPNOGRAFO MONITOR EMMA CON AL | D36: CAPNOGRAFO MONITOR EMMA CON ALARMA MEDICION MMHG | E36: HOSPITAL | F36: SIN MODELO | G36: SIN MARCA | H36: SIN SERIE | I36: 0
A37: 41942 | B37: D13516 | C37: CARRO TRANSP COMPUTADOR | D37: CARRO TRANSP COMPUTADOR | E37: HOSPITAL | F37: SIN MODELO | G37: SIN MARCA | H37: SIN SERIE | I37: 10606-14302
A38: 41942 | B38: D13517 | C38: CARRO PORTA CILINDROS | D38: CARRO DE TRANSPORTE PEQUEÑO DE GASES | E38: HOSPITAL | F38: SIN MODELO | G38: SIN MARCA | H38: SIN SERIE | I38: 18599
A39: 41942 | B39: D13518 | C39: CENTRAL DE MONITOREO | D39: CPU | E39: HOSPITAL | F39: HIPERVISORVY | G39: MINDRAY/LENOVO | H39: AF05100666 | I39: 8135
A40: 41942 | B40: D13519 | C40: CENTRIFUGA CLAY ADAMS DYNAC | D40: CENTRIFUGA CLAY ADAMS DYNAC | E40: FUCS | F40: PR-7000M | G40: CLAY ADAMS | H40: 268078 | I40: 5607
...

Sheet Correctivo menor
A1: BDG-BASTA-00007156 | B1: 3770 | C1: 41942 | D1: 2019-10-02 11:00:00 | E1: 2019-10-02 10:00:00 | F1: -NO_DEFINIDO - Se realiza ajuste de indicador de peso de la báscula que se bloqueaba | G1: Correctivo menor | H1: Bascula Con Tallimetro | I1: 19426 | J1: 10000001187681 | K1: 6 | L1: 1 | M1: 1798.4583 | N1: 0.0033361907 | O1: 299.74306 | P1: 0.0033361907 | Q1: 0.1814096 | R1: 0.70409287 | S1: #N/A
A2: BMO-TRMOH-00014894 | B2: 3074.5 | C2: 41942 | D2: 2020-03-25 10:30:00 | E2: 2020-02-25 10:00:00 | F2: -NO_DEFINIDO - CREADA DESDE AMsi&#x0D; Reclasificada desde la compañía 8 por el usuario JBARRERA&#x0D; &#x0D; Se realiza revisión del termohigrometro, se ajusta batería y queda funcionando correctamente. | G2: Correctivo menor | H2: Termohigrometro Digital | I2: 14894 | J2: N/A | K2: 2 | L2: 696.5 | M2: 1973.4375 | N2: 0.00101346 | O2: 986.71875 | P2: 0.00101346 | Q2: 0.058995729 | R2: 0.30569616 | S2: #N/A
A3: BAN-LARIN-00000768 | B3: 3770.5833 | C3: 41942 | D3: 2021-05-21 07:15:00 | E3: 2021-05-21 06:50:00 | F3: -NO_DEFINIDO - CREADA DESDE AMsi&#x0D; Reclasificada desde la compañía 8 por el usuario JBARRERA&#x0D; &#x0D; Se realiza revisión general del equipo, se evidencia socket sucio y desajustado, se realiza el ajuste necesario y pruebas de funcionamiento satisfactorias. Equipo operativo en el servicio | G3: Correctivo menor | H3: Laringoscopio | I3: 768 | J3: N/A | K3: 3 | L3: 0.41666667 | M3: 2395.3021 | N3: 0.0012524516 | O3: 798.43403 | P3: 0.0012524516 | Q3: 0.072392973 | R3: 0.36293436 | S3: #N/A
A4: BMO-TRMOH-00014607 | B4: 1011.6667 | C4: 41942 | D4: 2022-05-20 09:30:00 | E4: 2022-05-20 08:00:00 | F4: 18/05/2022-NO_DEFINIDO - Solicitud de Servico Creada desde AMSi, 03/06/2022-Novatecnica - Se realiza ajuste de carcasa de termohigrómetro, se realiza pruebas y equipo queda funcionando correctamente, se realiza instalación del termohigrómetro y se entrega al servicio en buenas condiciones. se recomienda al personal el cuidado de estos equipos. | G4: Correctivo menor | H4: Termometro Digital | I4: 14607 | J4: N/A | K4: 3 | L4: 1.5 | M4: 2759.3958 | N4: 0.0010871945 | O4: 919.79861 | P4: 0.0010871945 | Q4: 0.063149602 | R4: 0.3238836 | S4: #N/A
A5: OTP-CAMIL-00007665 | B5: 970.70833 | C5: 41942 | D5: 2022-06-30 08:00:00 | E5: 2022-06-30 07:00:00 | F5: 28/06/2022-NO_DEFINIDO - Solicitud de Servico Creada desde AMSi, 01/07/2022-Senior - Se realiza la Verificación de funcionamiento, encontrando baranda con seguros desajustados , se procede a realizar el ajuste mécanico pertinente, pruebas de funcionamiento OK. Se adjunta reporte de servicio. | G5: Correctivo menor | H5: Camilla De Transporte | I5: 7665/9976 | J5: N/A | K5: 3 | L5: 1 | M5: 2800.3333 | N5: 0.001071301 | O5: 933.44444 | P5: 0.001071301 | Q5: 0.062255788 | R5: 0.32000401 | S5: #N/A
A6: OTP-CAMIL-00000271 | B6: 935.57361 | C6: 41942 | D6: 2022-08-04 14:00:00 | E6: 2022-08-04 10:14:00 | F6: 01/08/2022-NO_DEFINIDO - Solicitud de Servico Creada desde AMSi, 09/08/2022-Senior - Se realiza inspección de la cama encontrando la baranda sin tornilleria de ajsute, se procede con la instalación de tornillos nuevos. Se realizan pruebas y funciona ok. Se adjunta reporte de servicio. | G6: Correctivo menor | H6: Camilla De Transporte | I6: 271 | J6: N/A | K6: 2 | L6: 3.7666667 | M6: 2835.5833 | N6: 0.00070532224 | O6: 1417.7917 | P6: 0.00070532224 | Q6: 0.041436371 | R6: 0.22424304 | S6: #N/A
A7: BDG-TENAT-00012861 | B7: 931.3625 | C7: 41942 | D7: 2022-08-09 09:25:00 | E7: 2022-08-08 15:18:00 | F7: 07/08/2022-NO_DEFINIDO - Solicitud de Servico Creada desde AMSi, 08/08/2022-Biomedico1 - Se retira tensiometro el cual se encuentra roto servicio informa que el equipo fu entragado roto, 09/08/2022-Biomedico1 - Se realiza ajuste de tensiometro con pegamento se realizan pruebas de funcionamiento equipo funciona correctamente se recomienda al servicio tener precaucion a la hora de manejar los equipos biomedicos | G7: Correctivo menor | H7: Tensiometro De Atril | I7: 12861 | J7: N/A | K7: 4 | L7: 18.116667 | M7: 2840.3924 | N7: 0.0014082561 | O7: 710.09809 | P7: 0.0014082561 | Q7: 0.081024089 | R7: 0.39768349 | S7: #N/A
A8: BFE-FOTOF-00016943 | B8: 903.70417 | C8: 41942 | D8: 2022-09-05 09:00:00 | E8: 2022-09-05 07:06:00 | F8: 03/09/2022-NO_DEFINIDO - Solicitud de Servico Creada desde AMSi, 05/10/2022-Senior - Se realiza ajuste de soporte ya que se encontró fracturado. OBS. El equipo ya previamente había sido reparado | G8: Correctivo menor | H8: Fotoforo | I8: 16943 | J8: N/A | K8: 2 | L8: 1.9 | M8: 2867.375 | N8: 0.00069750207 | O8: 1433.6875 | P8: 0.00069750207 | Q8: 0.040986497 | R8: 0.22205601 | S8: #N/A
A9: OTP-CAMIL-00015639 | B9: 721.61806 | C9: 41942 | D9: 2023-03-06 09:40:00 | E9: 2023-03-06 09:10:00 | F9: 14/02/2023-NO_DEFINIDO - Solicitud de Servico Creada desde AMSi, 06/03/2023-Senior - Se retira camilla, para realizar ajuste de baranda | G9: Correctivo menor | H9: Camilla De Transporte | I9: 15639 | J9: N/A | K9: 5 | L9: 0.5 | M9: 3049.4028 | N9: 0.0016396653 | O9: 609.88056 | P9: 0.0016396653 | Q9: 0.093695484 | R9: 0.44582764 | S9: #N/A
A10: BDG-TERMO-00014954 | B10: 738.66944 | C10: 41942 | D10: 2023-02-17 08:05:00 | E10: 2023-02-17 07:56:00 | F10: 15/02/2023-NO_DEFINIDO - Solicitud de Servico Creada desde AMSi, 23/02/2023-Biomedico1 - Se realiza ajuste de termómetro y se deja nuevamente en la sala 1 | G10: correctivo menor | H10: Termohigrometro Digital | I10: 14954 | J10: N/A | K10: 1 | L10: 0.15 | M10: 3032.3368 | N10: 0.00032977867 | O10: 3032.3368 | P10: 0.00032977867 | Q10: 0.019592248 | R10: 0.11194386 | S10: #N/A
A11: BDG-BASME-00007880 | B11: 735.375 | C11: 41942 | D11: 2023-02-20 15:45:00 | E11: 2023-02-20 15:00:00 | F11: 20/02/2023-NO_DEFINIDO - Solicitud de Servico Creada desde AMSi, 22/02/2023-Biomedico2 - Se realiza verificación de bascula con masas patron y se evidencia desajuste en mediciones,se retira y se reporta por garantía | G11: correctivo menor | H11: Bascula Mecanica | I11: 7880 | J11: N/A | K11: 4 | L11: 0.75 | M11: 3035.6562 | N11: 0.0013176722 | O11: 758.91406 | P11: 0.0013176722 | Q11: 0.076015826 | R11: 0.37771806 | S11: #N/A
A12: BDG-TERMO-00014955 | B12: 704.49931 | C12: 41942 | D12: 2023-03-23 12:05:00 | E12: 2023-03-23 12:01:00 | F12: 22/03/2023-NO_DEFINIDO - Solicitud de Servico Creada desde AMSi, 30/03/2023-Biomedico1 - Re realiza inspección de termohigometro sala de cirugía se realiza ajuste de sonda de temperatura equipo funciona correctamente | G12: correctivo menor | H12: Termohigrometro Digital | I12: 14955 | J12: N/A | K12: 1 | L12: 0.066666667 | M12: 3066.5035 | N12: 0.00032610431 | O12: 3066.5035 | P12: 0.00032610431 | Q12: 0.019376082 | R12: 0.11076839 | S12: #N/A
A13: BDG-BASTA-00005941 | B13: 458.41667 | C13: 41942 | D13: 2023-11-24 16:00:00 | E13: 2023-11-24 14:00:00 | F13: 23/11/2023-NO_DEFINIDO - Solicitud de Servico Creada desde AMSi, 05/12/2023-Senior - Se realiza ajuste en tallímetro, reforzando los remache que sostiene la estructura | G13: Correctivo menor | H13: Bascula Con Tallimetro | I13: 5941 | J13: N/A | K13: 5 | L13: 2 | M13: 3312.6667 | N13: 0.001509358 | O13: 662.53333 | P13: 0.001509358 | Q13: 0.086581826 | R13: 0.41921166 | S13: #N/A
A14: BDG-EQUIO-00018895 | B14: 329.61597 | C14: 41942 | D14: 2024-04-01 09:39:00 | E14: 2024-04-01 09:13:00 | F14: 26/03/2024-NO_DEFINIDO - Solicitud de Servico Creada desde AMSi, 01/04/2024-Biomedico1 - Se realiza ajuste se cono se realizan pruebas equipo funciona correctamente | G14: Correctivo menor | H14: Equipo De Organos Portatil | I14: 18895/18896 | J14: N/A | K14: 2 | L14: 0.43333333 | M14: 3441.4021 | N14: 0.00058115848 | O14: 1720.701 | P14: 0.00058115848 | Q14: 0.034268572 | R14: 0.18878086 | S14: 400000
A15: BDG-EQUIO-00014198 | B15: 145.65903 | C15: 41942 | D15: 2024-10-02 08:35:00 | E15: 2024-10-02 08:11:00 | F15: 19/09/2024-NO_DEFINIDO - Solicitud de Servico Creada desde AMSi, 02/10/2024-Biomedico1 - Se realiza ajuste de equipo de organos a la pared ya que se encontró en riesgo de caer al piso se ajusta se realizan pruebas de funcionamiento | G15: Correctivo menor | H15: Equipo De Organos Portatil | I15: 14198 | J15: N/A | K15: 1 | L15: 0.4 | M15: 3625.3576 | N15: 0.00027583486 | O15: 3625.3576 | P15: 0.00027583486 | Q15: 0.016413891 | R15: 0.09452947 | S15: #N/A
A16: BDG-EQUIO-00018895 | B16: 147.62639 | C16: 41942 | D16: 2024-09-30 09:55:00 | E16: 2024-09-30 08:58:00 | F16: 25/09/2024-NO_DEFINIDO - Solicitud de Servico Creada desde AMSi, 30/09/2024-Biomedico1 - Se realiza ajuste de cabezal de otoscopio ya que al hacer el anclaje con el mango no enciende se ajusta se realizan pruebas equipo funcionando correctamente | G16: Correctivo menor | H16: Equipo De Organos Portatil | I16: 18895/18896 | J16: N/A | K16: 2 | L16: 0.95 | M16: 3623.4132 | N16: 0.00055196576 | O16: 1811.7066 | P16: 0.00055196576 | Q16: 0.03257555 | R16: 0.18021049 | S16: 400000
A17: BFE-LAMAU-00000237 | B17: 1538.375 | C17: 41942 | D17: 2020-12-09 15:20:00 | E17: 2020-12-09 15:00:00 | F17: -NO_DEFINIDO - Se realiza revisión física y funcional de lámpara cuello de cisne, se encuentra cable suelto, se realiza ajuste del mismo y pruebas funcionales satisfactorias. | G17: Correctivo menor | H17: Lampara Auxiliar De Procedimientos | I17: 237/14680 | J17: N/A | K17: 2 | L17: 0.33333333 | M17: 2232.6389 | N17: 0.00089580093 | O17: 1116.3194 | P17: 0.00089580093 | Q17: 0.052329164 | R17: 0.27565562 | S17: 600000
A18: BDG-TENAT-00012865 | B18: 174.68611 | C18: 41942 | D18: 2024-09-03 11:33:00 | E18: 2024-09-03 07:32:00 | F18: 21/08/2024-NO_DEFINIDO - Solicitud de Servico Creada desde AMSi, 03/09/2024-Biomedico1 - Se realiza pegado de base de tensiómetro ya que se encontró roto se deja secar por un tiepo prolongado se realiza ajuste y adecuacion de tensiómetro se realiza entrga al servicio para su respectiva limpieza y desinfección | G18: Correctivo menor | H18: Tensiometro De Atril | I18: 12865 | J18: N/A | K18: 4 | L18: 4.0166667 | M18: 3596.4812 | N18: 0.0011121982 | O18: 899.12031 | P18: 0.0011121982 | Q18: 0.064554032 | R18: 0.32994224 | S18: #N/A
A19: BAN-LARIN-00015725 | B19: 1418.5625 | C19: 41942 | D19: 2021-04-08 10:55:00 | E19: 2021-04-08 10:30:00 | F19: -NO_DEFINIDO - Se realiza revisión general del equipo, se evidencia socket con suciedad y desajustado. &#x0D; Se realiza limpieza y ajuste de bombilla, equipo operativo en el servicio. | G19: Correctivo menor | H19: Laringoscopio | I19: 15725 | J19: N/A | K19: 2 | L19: 0.41666667 | M19: 2352.4549 | N19: 0.00085017572 | O19: 1176.2274 | P19: 0.00085017572 | Q19: 0.049731348 | R19: 0.26365996 | S19: #N/A
A20: BFE-FOTOF-00015060 | B20: 1411.6458 | C20: 41942 | D20: 44301.368 | E20: 2021-04-15 08:30:00 | F20: -NO_DEFINIDO - Se realiza ajuste de cable de fotóforo ya que presentaba interferencia. &#x0D; se realizan pruebas de funcionamiento satisfactorias. &#x0D; Equipo operativo en el servicio | G20: Correctivo menor | H20: Fotoforo | I20: 15060 | J20: N/A | K20: 3 | L20: 0.33333333 | M20: 2359.3681 | N20: 0.0012715269 | O20: 786.45602 | P20: 0.0012715269 | Q20: 0.073454028 | R20: 0.36729417 | S20: #N/A
A21: BFE-FOTOF-00018993 | B21: 24.368056 | C21: 41942 | D21: 2025-01-31 15:30:00 | E21: 2025-01-31 15:10:00 | F21: 08/11/2024-NO_DEFINIDO - Solicitud de Servico Creada desde AMSi, 30/01/2025-Biomedico1 - Se realiza verificación del adaptador de carga del equipo se evidencia que el cargador se encuentra en falla se instala un cargador de backup se realizan pruebas de funcionamiento equipo funcionando correctamente | G21: Correctivo menor | H21: Fotoforo | I21: 18993 | J21: N/A | K21: 1 | L21: 0.33333333 | M21: 3746.6458 | N21: 0.0002669054 | O21: 3746.6458 | P21: 0.0002669054 | Q21: 0.015886776 | R21: 0.091614057 | S21: #N/A
A22: BFT-ELIPT-00015248 | B22: 1957.4167 | C22: 41942 | D22: 2019-10-17 15:00:00 | E22: 2019-10-17 14:00:00 | F22: -NO_DEFINIDO - Se realiza inspección física inicial, verificación de encendido, puesta en marcha en modos de trabajo, inclinación y velocidad, limpieza general externa de display,labels de acción, chasis del equipo, se realiza lubricación de la banda y verificación de voltaje. Equipo funciona correctamente. | G22: Correctivo menor | H22: Eliptica | I22: 15248 | J22: N/A | K22: 8 | L22: 1 | M22: 1813.625 | N22: 0.0044110552 | O22: 226.70312 | P22: 0.0044110552 | Q22: 0.2325357 | R22: 0.79566202 | S22: #N/A
A23: BDG-BASTA-00007156 | B23: 1972.6458 | C23: 41942 | D23: 2019-10-02 08:30:00 | E23: 2019-10-02 08:30:00 | F23: -NO_DEFINIDO - OT generada automáticamente por la solicitud No. 16143&#x0D; &#x0D; Diagnóstico S.S: Indicador de báscula presenta falla y no funciona.&#x0D; &#x0D; Comentario S.S:Se realiza ajuste de indicador de peso de la báscula que se bloqueaba | G23: Correctivo menor | H23: Bascula Con Tallimetro | I23: 19426 | J23: 10000001187681 | K23: 6 | L23: 0 | M23: 1798.4583 | N23: 0.0033361907 | O23: 299.74306 | P23: 0.0033361907 | Q23: 0.1814096 | R23: 0.69911545 | S23: #N/A
A24: BMO-TRMOH-00014155 | B24: 1967.4583 | C24: 41942 | D24: 2019-10-07 13:30:00 | E24: 2019-10-07 13:00:00 | F24: -NO_DEFINIDO - Se realiza revisión de termohigrometro, se ajusta y se realiza limpieza general. Equipo funciona correctamente. | G24: Correctivo menor | H24: Termohigrometro Digital | I24: 14155 | J24: N/A | K24: 3 | L24: 0.5 | M24: 1803.5625 | N24: 0.0016633746 | O24: 601.1875 | P24: 0.0016633746 | Q24: 0.094983836 | R24: 0.45053755 | S24: #N/A
A25: BMO-TRMOH-00014155 | B25: 1965.6458 | C25: 41942 | D25: 2019-10-09 09:00:00 | E25: 2019-10-09 08:30:00 | F25: -NO_DEFINIDO - Se realiza revisión de remohigrometro el cuál está funcionando correctamente, se realiza ajuste de temperatura programada en la nevera. Equipo funcional. | G25: Correctivo menor | H25: Termohigrometro Digital | I25: 14155 | J25: N/A | K25: 3 | L25: 0.5 | M25: 1805.375 | N25: 0.0016617046 | O25: 601.79167 | P25: 0.0016617046 | Q25: 0.094893152 | R25: 0.45020713 | S25: #N/A
A26: BMO-TRMOH-00014157 | B26: 1944.4792 | C26: 41942 | D26: 2019-10-30 13:00:00 | E26: 2019-10-30 12:30:00 | F26: -NO_DEFINIDO - El termohrigrometro evidencia daño en el display por caída, se encuentra una parte de la pantalla rota, se repara y equipo queda funcional. | G26: Correctivo menor | H26: Termohigrometro Digital | I26: 14157 | J26: N/A | K26: 2 | L26: 0.5 | M26: 1826.5417 | N26: 0.0010949654 | O26: 913.27083 | P26: 0.0010949654 | Q26: 0.063586313 | R26: 0.32577241 | S26: #N/A
A27: BMO-TRMOH-00014157 | B27: 1967.6667 | C27: 41942 | D27: 2019-10-07 08:30:00 | E27: 2019-10-07 08:00:00 | F27: -NO_DEFINIDO - Se realiza revisión de termohigrometro se realizan pruebas, equipo patrón: 4.3°C; Equipo: 4.3°C. Equipo funciona correctamente. | G27: Correctivo menor | H27: Termohigrometro Digital | I27: 14157 | J27: N/A | K27: 2 | L27: 0.5 | M27: 1803.3542 | N27: 0.0011090445 | O27: 901.67708 | P27: 0.0011090445 | Q27: 0.064377007 | R27: 0.32918106 | S27: #N/A
A28: BFT-BANTR-00015249 | B28: 1930.5729 | C28: 41942 | D28: 2019-11-14 07:00:00 | E28: 2019-11-13 10:15:00 | F28: -NO_DEFINIDO - Se realiza cambio de interruptor de encendido por daño. Equipo queda funcionando correctamente. | G28: Correctivo menor | H28: Banda Trotadora | I28: 15249 | J28: N/A | K28: 3 | L28: 20.75 | M28: 1841.2917 | N28: 0.001629291 | O28: 613.76389 | P28: 0.001629291 | Q28: 0.093131173 | R28: 0.44375408 | S28: #N/A
A29: BFT-BANTR-00015250 | B29: 1917.6667 | C29: 41942 | D29: 2019-11-26 08:45:00 | E29: 2019-11-26 08:00:00 | F29: -NO_DEFINIDO - Se realiza cambio de interruptor de encendido por daño. Equipo se realizan pruebas y queda funcionando correctamente. | G29: Correctivo menor | H29: Banda Trotadora | I29: 15250 | J29: N/A | K29: 4 | L29: 0.75 | M29: 1853.3646 | N29: 0.002158237 | O29: 463.34115 | P29: 0.002158237 | Q29: 0.12146033 | R29: 0.54020076 | S29: #N/A
A30: BFT-BANTR-00015250 | B30: 1917.5 | C30: 41942 | D30: 2019-11-26 12:45:00 | E30: 2019-11-26 12:00:00 | F30: -NO_DEFINIDO - Se realiza ajuste de banda y lubricación de partes moviles. Equipo funcionando correctamente. | G30: Correctivo menor | H30: Banda Trotadora | I30: 15250 | J30: N/A | K30: 4 | L30: 0.75 | M30: 1853.5312 | N30: 0.0021580429 | O30: 463.38281 | P30: 0.0021580429 | Q30: 0.1214501 | R30: 0.54016863 | S30: #N/A
A31: BDG-TENAT-00012859 | B31: 1928.625 | C31: 41942 | D31: 2019-11-15 10:00:00 | E31: 2019-11-15 09:00:00 | F31: -NO_DEFINIDO - Se realiza revisión de microscopio el cuál se encontraba opaco. Equipo funciona correctamente. | G31: Correctivo menor | H31: Tensiometro De Atril | I31: 12859 | J31: N/A | K31: 4 | L31: 1 | M31: 1842.4167 | N31: 0.0021710616 | O31: 460.60417 | P31: 0.0021710616 | Q31: 0.12213609 | R31: 0.54231869 | S31: #N/A
A32: BQX-SICOR-00007836 | B32: 1804.5417 | C32: 41942 | D32: 2020-03-18 11:45:00 | E32: 2020-03-18 11:00:00 | F32: -NO_DEFINIDO - Se realiza revisión de la sierra, presentaba daño en switch interruptor, se corrige y queda funcionando correctamente. | G32: Correctivo menor | H32: Sierra Corta Yesos | I32: 7836 | J32: N/A | K32: 3 | L32: 0.75 | M32: 1966.4896 | N32: 0.0015255611 | O32: 655.49653 | P32: 0.0015255611 | Q32: 0.087469405 | R32: 0.4225896 | S32: #N/A
A33: BAN-LARIN-00013553 | B33: 1788.6667 | C33: 41942 | D33: 2020-04-03 08:30:00 | E33: 2020-04-03 08:00:00 | F33: -NO_DEFINIDO - Se realiza verificación de laringoscopio, limpieza y ajuste de resorte de contacto. Equipo funciona correctamente. | G33: Correctivo menor | H33: Laringoscopio | I33: 13553 | J33: N/A | K33: 1 | L33: 0.5 | M33: 1982.3542 | N33: 0.00050445073 | O33: 1982.3542 | P33: 0.00050445073 | Q33: 0.029813583 | R33: 0.16606704 | S33: #N/A
A34: BFE-CARTR-00000000 | B34: 1789.6667 | C34: 41578 | D34: 2020-04-02 16:00:00 | E34: 2020-04-02 08:00:00 | F34: -NO_DEFINIDO - Se realiza revisión del carro donde se evidencia que se rompió una rueda, se retiro de la torre al taller de ingeniería para reparación.&#x0D; &#x0D; Se realiza ajuste de rueda, se ajusta rueda en la torre, adicionalmente se ajusta soporte del cilindro, se realiza lubricación y se realiza ajuste de soportes de la base. Carro de transporte queda funcionando correctamente | G34: Correctivo menor | H34: Carro de Trasporte (Torre Artroscopia) | J34: N/A | K34: 1 | L34: 8 | M34: 2345.6667 | N34: 0.00042631803 | O34: 2345.6667 | P34: 0.00042631803 | Q34: 0.025254709 | R34: 0.14227736 | S34: #N/A
A35: BAN-LARIN-00013668 | B35: 1768.7083 | C35: 41942 | D35: 2020-04-23 07:30:00 | E35: 2020-04-23 07:00:00 | F35: -NO_DEFINIDO - Se verifica laringoscopio, se hace limpieza de socket y equipo queda funcionando correctamente. | G35: Correctivo menor | H35: Laringoscopio | I35: 13668 | J35: N/A | K35: 3 | L35: 0.5 | M35: 2002.3125 | N35: 0.0014982676 | O35: 667.4375 | P35: 0.0014982676 | Q35: 0.085973814 | R35: 0.4168882 | S35: #N/A
A36: BDG-EQUIO-00013803 | B36: 1748.6667 | C36: 41942 | D36: 2020-05-13 08:30:00 | E36: 2020-05-13 08:00:00 | F36: -NO_DEFINIDO - Se realiza revisión Eequipo, Se realiza el ajuste y equipo queda funcionando correctamente. | G36: Correctivo menor | H36: Equipo Organos De Los Sentidos | I36: 13803 | J36: N/A | K36: 5 | L36: 0.5 | M36: 2022.3542 | N36: 0.0024723662 | O36: 404.47083 | P36: 0.0024723662 | Q36: 0.13786376 | R36: 0.58936553 | S36: #N/A
