Workbook
Name OLE_LINK1: 'CODIGOS ACTIVOS'!$A$529

Sheet Compras
A1: PEDIDO AREA DE ING BIOMEDICA ABRIL 2024.xlsx | B1: Columna1 | C1: CODIGO | D1: DESCRIPCION | E1: CANTIDAD | F1: ENTREGADO | G1: FECHA DE ENTREGA | H1: FALTANTE | I1: CENTRO DE COSTOS | J1: ABRI | K1: 2024 | L1: Observaciones de fechas de entrega ( 1pimera fecha y segunda y ETC
A2: 45078 | C2: Q252796 | D2: Sensor De Saturación Drager Adulto Nellcor | E2: 2 | F2: 2 | H2: 0 | I2: (2) Salas de cirugía 4 piso | J2: 6 | K2: 2023
A3: 45078 | C3: A250071 | D3: Cable ECG 5 Derivadas Drager | E3: 1 | F3: 1 | H3: 0 | I3: (1) Salas de cirugía 4 piso | J3: 6 | K3: 2023
A4: 45078 | C4: A250003 | D4: Sensor SPO2 mec 1200 neonatal | E4: 2 | F4: 2 | H4: 0 | I4: (2) Urgencias | J4: 6 | K4: 2023
A5: 45078 | C5: A289799 | D5: Cable De Alimentacion Grado Hospitalario | E5: 3 | F5: 2 | H5: 1 | I5: (1) Urgencias, (2) Salas de cirugía 4 piso | J5: 6 | K5: 2023
A6: 45078 | C6: A171049 | D6: Bombillo Laringoscopío Ref: 6000 | E6: 3 | F6: 3 | H6: 0 | I6: (1) Urgencias, (2) Salas de cirugía 4 piso | J6: 6 | K6: 2023
A7: 45078 | C7: A258988 | D7: Multimed Drager | E7: 1 | F7: 1 | H7: 0 | I7: (1) Salas de cirugía 4 piso | J7: 6 | K7: 2023
A8: 45108 | C8: Q252796 | D8: Sensor De Saturación Drager Adulto Nellcor | E8: 2 | F8: 2 | H8: 0 | I8: (3) Salas de cirugía 4 piso | J8: 7 | K8: 2023
A9: 45108 | C9: Q252746 | D9: Sensor De Saturación Mindray UMEC10 Neonatal Original | E9: 1 | F9: 1 | H9: 0 | I9: (1) Salas de cirugía 4 piso | J9: 7 | K9: 2023
A10: 45108 | C10: A289799 | D10: Cable De Alimentacion Grado Hospitalario | E10: 1 | F10: 1 | H10: 0 | I10: (1) Salas de cirugía 4 piso | J10: 7 | K10: 2023
A11: 45108 | C11: A251139 | D11: Sensor De Saturación Mindray IMEC10 Adultos | E11: 7 | F11: 7 | H11: 0 | I11: (3) Urgencias, (2)Hospitalización, (2) Salas de cirugia 4 piso | J11: 7 | K11: 2023
A12: 45108 | C12: L619246 | D12: Toco de Frecuencias Uterina monitor fetal Corometrics 170 | E12: 1 | H12: 1 | I12: (1) Salas de cirugía 4 piso | J12: 7 | K12: 2023
A13: 45108 | C13: Q252732 | D13: Sensor De Saturación Cardiocap GE Adultos | E13: 2 | F13: 2 | H13: 0 | I13: (2) Salas de cirugía 4 piso | J13: 7 | K13: 2023
A14: 45108 | C14: A250034 | D14: Manguera NIBP para Monitor De Signos Vitales Cardiocap | E14: 2 | F14: 2 | H14: 0 | I14: (2) Salas de cirugía 4 piso | J14: 7 | K14: 2023
A15: 45108 | C15: Q252747 | D15: Brazalete Adulto 1 Vias | E15: 5 | F15: 5 | H15: 0 | I15: (1) Urgencias, (2)Hospitalización, (2) Salas de cirugia 4 piso | J15: 7 | K15: 2023
A16: 45108 | C16: Q252509 | D16: Conector Para Brazalete | E16: 12 | F16: 12 | H16: 0 | I16: (3) Urgencias, (6)Hospitalización, (3) Salas de cirugia 4 piso | J16: 7 | K16: 2023
A17: 45108 | C17: A250075 | D17: Interfaz De Spo2 Drager | E17: 1 | F17: 1 | H17: 0 | I17: (1) Salas de cirugía 4 piso | J17: 7 | K17: 2023
A18: 45108 | C18: Q250011 O Q252863 | D18: Bateria Monitor Signos Vitales Mindray Mec1200 | E18: 2 | F18: 2 | H18: 0 | I18: (2) Urgencias | J18: 7 | K18: 2023
A19: 45139 | C19: Q250003 | D19: Sensor De Saturación Mindray MEC1200 Adulto | E19: 5 | F19: 5 | H19: 0 | I19: 2 (Salas de cx recuperación), 1 (Hospitalización) | J19: 8 | K19: 2023
A20: 45139 | C20: Q252746 | D20: Sensor De Saturación Mindray UMEC10 Neonatal Original | E20: 1 | F20: 1 | H20: 0 | I20: 1 ( Sala de partos) | J20: 8 | K20: 2023
A21: 45139 | C21: A289799 | D21: Cable De Alimentacion Grado Hospitalario | E21: 2 | F21: 2 | H21: 0 | I21: 2 (Urgencias) | J21: 8 | K21: 2023
A22: 45139 | C22: Q250011 O Q252863 | D22: Bateria Monitor Signos Vitales Mindray Mec1200 | E22: 2 | F22: 2 | H22: 0 | I22: 2 (Salas de cx partos) | J22: 8 | K22: 2023
A23: 45139 | C23: Q252804 | D23: Cable ECG 3 Derivadas Mindray Mec1200 | E23: 3 | F23: 3 | H23: 0 | I23: 2 (Salas de cx recuperación), 1 (Hospitalización) | J23: 8 | K23: 2023
A24: 45139 | C24: Q283204 | D24: Cable ECG 3 Derivadas Mindray Umec | E24: 2 | F24: 2 | H24: 0 | I24: 1 (Salas de cx partos), 1 (Salas de cx recuperación) | J24: 8 | K24: 2023
... A40: 45200 | C40: Q252747 | D40: Brazalete Adulto 1 Vias | E40: 10 | F40: 10 | H40: 0 | I40: (1) Rehabilitación, (3) urgencias, (1) hospitalización 2D, (1) hospitalización 5a, (1) recuperación cx, (2) salas 4 piso, (1) salas 2 piso | J40: 10 | K40: 2023
A41: 45200 | C41: Q252748 | D41: Brazalete Adulto 2 Vias | E41: 4 | H41: 4 | I41: 3 Consulta externa (Cons 7, 17, 19), 1 Hospitalización | J41: 10 | K41: 2023
A42: 45200 | C42: A250013 | D42: Sensor De Saturación Mindray IMEC10 Neonatal | E42: 3 | F42: 3 | H42: 0 | I42: 3 Urgencias, | J42: 10 | K42: 2023
A43: 45200 | C43: NUEVO | D43: Sensor De Saturación Drager Adulto Nellcor ORIGINAL | E43: 2 | H43: 2 | J43: 10 | K43: 2023
A44: 45200 | C44: A250075 | D44: Interfaz De Spo2 Drager | E44: 1 | F44: 1 | H44: 0 | I44: Salas de cirugia 4 piso | J44: 10 | K44: 2023
A45: 45200 | C45: Q250011 O Q252863 | D45: Bateria Monitor Signos Vitales Mindray Mec1200 | E45: 5 | F45: 5 | H45: 0 | I45: (5) Urgencias | J45: 10 | K45: 2023
A46: 45231 | C46: Q252747 | D46: Brazalete Adulto 1 Vias | E46: 10 | F46: 10 | G46: 45250 | H46: 0 | I46: (2) urgencias adultos, (1) hospitalización 5a, (1) hospitalización 4 alta dependencia, (3) recuperación salas cx, (1) hospitalización 2d, (1) hospitalización 3b, (1) hospitalización 2a | J46: 11 | K46: 2023
A47: 45231 | C47: Q252748 | D47: Brazalete Adulto 2 Vias | E47: 10 | F47: 10 | H47: 0 | I47: (10)Consulta externa, (1)Hospitalización 2B | J47: 11 | K47: 2023
A48: 45231 | C48: Q252815 | D48: Pera Con Valvula Para Tensiometro | E48: 15 | F48: 15 | G48: 45244 | H48: 0 | I48: (15)Consulta externa | J48: 11 | K48: 2023
A49: 45231 | C49: Q252746 | D49: Sensor De Saturación Mindray UMEC10 Neonatal Original | E49: 1 | F49: 1 | G49: 45250 | H49: 0 | I49: (1) Hospitalización 3b | J49: 11 | K49: 2023
A50: 45231 | C50: Q250011 O Q252863 | D50: Bateria Monitor Signos Vitales Mindray Mec1200 | E50: 2 | F50: 2 | G50: 45250 | H50: 0 | I50: (2) Salas de cx | J50: 11 | K50: 2023
A51: 45231 | C51: A251029 | D51: Brazalete Neonatal De 1 Via reusable manguera Azul- Medida ( 5.8 - 10.8) | E51: 2 | F51: 2 | G51: 45244 | H51: 0 | I51: (2) Hospitalización 2C y 2D | J51: 11 | K51: 2023
A52: 45231 | C52: Q252607 | D52: Brazalete Infante De 1 Via reusable manguera naranja- Medida ( 9-14.8) | E52: 2 | F52: 1 | G52: 45244 | H52: 1 | I52: (2) Hospitalización 2A y 2B | J52: 11 | K52: 2023
A53: 45231 | C53: Q252509 | D53: Conector Para Brazalete | E53: 5 | F53: 5 | G53: 45244 | H53: 0 | I53: (2) Hospitalización (VIP, 2C), (2) Sala cirugia, (1) urgencias | J53: 11 | K53: 2023
A54: 45231 | C54: A171049 | D54: Bombillo Laringoscopío Ref: 6000 | E54: 2 | F54: 2 | G54: 45244 | H54: 0 | I54: (1) urgencias pediatria (1) urgencias adulto | J54: 11 | K54: 2023
A55: 45231 | C55: NUEVO | D55: Manguera para conexión PNI (REF:MP00953) | E55: 2 | F55: 2 | G55: 45250 | H55: 0 | I55: (1) Radiologia-resonancia, (1) Salas cx | J55: 11 | K55: 2023
...

Sheet CODIGOS ACTIVOS
A1: DESCRIPCION | B1: CODIGO | C1: EXISTENCIAS | D1: SERVICIO
A2: ABINTRA SOBRE * 27GR | B2: M192241
A3: AGENDA ARGOLLADA | B3: A030062
A4: AGUA FRASCO * 300ML | B4: A020034
A5: AGUA OXIGENADA | B5: L012013
A6: AGUJA MULTIPLE VACUTAINER 21*1/2 CAJA*100 | B6: A191016
A7: AGUJA SEMIRRIGIDA BISC 3.6 FR | B7: L511066
A8: AGUJAS VIUDAS | B8: L511056
A9: ALAMBRE CERCLAJE 1.25MM C0125 | B9: A312891
A10: ALCOHOL ANTISEPTICO 70% X 700ML | B10: L012015
A11: ALCOHOL GLICERINADO * LITRO | B11: L012017
A12: ALGODON ROLLO X 454 GR | B12: L012020
A13: ALTHERA * 450 GR | B13: M192207
... A52: Bateria Monitor Signos Vitales Mindray Mec1200 | B52: Q250011 O Q252863
A53: Bateria Monitor Signos Vitales Procare 300
A54: Bateria Monitor Umec 10 | B54: NUEVO
A55: BISTURI 18MM BAUKER | B55: A031049
A56: BISTURI PLASTICO ENCAUCHETADO | B56: A031101
A57: BNS PROTEINA WHEY AISLADA*36gr | B57: M192222
A58: BOLSA AUTOSELLABLE 135*280mm*200 | B58: A271015
A59: BOLSA AUTOSELLABLE 190*330mm X 200UN | B59: A271008
A60: BOLSA AUTOSELLABLE 250*370mm X 200UN | B60: A271007
A61: BOLSA AUTOSELLABLE 70*230 X 200 | B61: A271014
A62: BOLSA AUTOSELLABLE 90*260mm X 200UN | B62: A271009
A63: BOLSA BASURA NEGRA 100X80 | B63: A023018
A64: BOLSA BASURA NEGRA PARA COMPACTADORA | B64: A023020
A65: BOLSA BASURA ROJA C2 100*80 | B65: A023021
... A86: Bombillo Lampara Cielitica | B86: A204002
A87: Bombillo Laringoscopío Ref: 2800
A88: Bombillo Laringoscopío Ref: 3400u | B88: A171078
A89: Bombillo Laringoscopío Ref: 3900 | B89: A171028
A90: Bombillo Laringoscopío Ref: 4700 | B90: A171027
A91: Bombillo Laringoscopío Ref: 4800 | B91: A171026
A92: Bombillo Laringoscopío Ref: 6000 | B92: A171049
A93: Bombillo Xenon 300W Olympus | B93: A171087
A94: BORRADOR DE NATA | B94: A031018
A95: BRAZALETE 2 VIAS INFANTIL DE 9 A 14.8 CM | B95: Q283246
A96: BRAZALETE ADULTO 1 VIA | B96: Q252747
A97: Brazalete Adulto 2 Vias | B97: Q252748
A98: Brazalete Adulto De 2 Vias Bariatrica Medida ( 33 - 47 ) | B98: Q250040
...

Sheet Hoja1
C2: DESCRIPCION | D2: CODIGO COMPRAS
C3: N/A | D3: N/A
C4: Aros De Bloqueo Cabezal De Equipo De Organos | D4: A250074
C5: Bateria Monitor Signos Vitales Mindray Mec1200 | D5: Q250011 O Q252863
C6: Bateria Monitor Signos Vitales Mindray IMEC10 | D6: Q250014
C7: Bateria Monitor Signos Vitales CardioCap | D7: Q252732
C8: Bateria Monitor Signos Vitales Procare 300
C9: Bombillo Laringoscopío Ref: 2800
C10: Bombillo Equipo de organos nuevo Ref: 3100u | D10: A171023
C11: Bombillo Laringoscopío Ref: 3400u | D11: A171078
C12: Bombillo Laringoscopío Ref: 3900 | D12: A171028
C13: Bombillo Laringoscopío Ref: 4700 | D13: A171027
C14: Bombillo Laringoscopío Ref: 4800 | D14: A171026
C15: Bombillo Laringoscopío Ref: 6000 | D15: A171049
C16: Bombillo Xenon 300W Olympus | D16: A171087
C17: Bombillo Lampara Cielitica | D17: A204002
C18: Brazalete Adulto 1 Vias | D18: Q252747
C19: Brazalete Adulto 2 Vias | D19: Q252748
C20: Brazalete Adulto De 2 Vias Bariatrica Medida ( 33 - 47 ) | D20: Q250040
C21: Brazalete Neonatal De1 Via Desechable Medida ( 7 - 13) | D21: Q252739
... C62: Pera Con Valvula Para Tensiometro | D62: Q252815
C63: Pera Con Valvula Para Infusor
C64: Sensor De Flujo Drager | D64: Q252772
C65: Sensor De Flujo G.E. Aestiva/5
C66: Sensor De Saturación Drager Adulto Nellcor | D66: Q252796
C67: Sensor De Saturación Drager Adulto Nellcor (Generico) | D67: A250134
C68: Sensor De Saturación Mindray MEC1200 Neonatal | D68: A250003
C69: Sensor De Saturación Mindray MEC1200 Adulto | D69: Q250003
C70: Sensor De Saturación Mindray IMEC10 Neonatal | D70: A250013
C71: Sensor De Saturación Mindray IMEC10 Adultos | D71: A251139
C72: Sensor De Saturación Mindray UMEC10 Neonatal Original | D72: Q252746
C73: Sensor De Saturación General Electric Procare 300 Adulto | D73: Q252822
C74: Sensor De Saturación Cardiocap GE Adultos | D74: Q252732
C75: Sensor De Saturación GE Adultos Datex Ohmeda B650 | D75: Q252835
C76: Sensor De Temperatura Transesofágico Monitor De Signos G.E | D76: Q252758
C77: Socket Laringoscopio Ref: 60813 | D77: A092046
... C84: Brazalete neonatales Hillroom - WELCHALLYN | D84: NUEVO

Sheet Hoja2
C2: DESCRIPCION | D2: DESCRIPCION | E2: Solicictado 4 años | F2: Gasto 4 años entregado | H2: promedio mes / entregado
C3: Sensor SPO2 mec 1200 neonatal | D3: Sensor SPO2 mec 1200 neonatal | E3: =SUMIF(Compras!D:D,D3,Compras!E:E) -> 2 | F3: =SUMIF(Compras!D:D,Hoja2!D3,Compras!F:F) -> 2 | G3: =E3/(4*12) -> 0.041666667 | H3: =F3/(4*12) -> 0.041666667
C4: Cable De Alimentacion Grado Hospitalario | D4: Cable De Alimentacion Grado Hospitalario | E4: =SUMIF(Compras!D:D,D4,Compras!E:E) -> 36 | F4: =SUMIF(Compras!D:D,Hoja2!D4,Compras!F:F) -> 23 | G4: =E4/(4*12) -> 0.75 | H4: =F4/(4*12) -> 0.47916667
C5: Bombillo Laringoscopío Ref: 6000 welch allyn | D5: Bombillo Laringoscopío Ref: 6000 | E5: =SUMIF(Compras!D:D,D5,Compras!E:E) -> 20 | F5: =SUMIF(Compras!D:D,Hoja2!D5,Compras!F:F) -> 8 | G5: =E5/(4*12) -> 0.41666667 | H5: =F5/(4*12) -> 0.16666667
C6: Sensor De Saturación Mindray UMEC10 Neonatal Original Monitor de signos vitales | D6: Sensor De Saturación Mindray UMEC10 Neonatal Original | E6: =SUMIF(Compras!D:D,D6,Compras!E:E) -> 40 | F6: =SUMIF(Compras!D:D,Hoja2!D6,Compras!F:F) -> 28 | G6: =E6/(4*12) -> 0.83333333 | H6: =F6/(4*12) -> 0.58333333
C7: Sensor De Saturación Mindray IMEC10 Adultos Monitor de signos vitales | D7: Sensor De Saturación Mindray IMEC10 Adultos | E7: =SUMIF(Compras!D:D,D7,Compras!E:E) -> 127 | F7: =SUMIF(Compras!D:D,Hoja2!D7,Compras!F:F) -> 96 | G7: =E7/(4*12) -> 2.6458333 | H7: =F7/(4*12) -> 2
C8: Toco de actividad Uterina monitor fetal general Corometrics 170 | D8: Toco de Frecuencias Uterina monitor fetal Corometrics 170 | E8: =SUMIF(Compras!D:D,D8,Compras!E:E) -> 25 | F8: =SUMIF(Compras!D:D,Hoja2!D8,Compras!F:F) -> 8 | G8: =E8/(4*12) -> 0.52083333 | H8: =F8/(4*12) -> 0.16666667
C9: Sensor De Saturación Cardiocap S5 GE Adultos Monitor de signos vitales | D9: Sensor De Saturación Cardiocap GE Adultos | E9: =SUMIF(Compras!D:D,D9,Compras!E:E) -> 11 | F9: =SUMIF(Compras!D:D,Hoja2!D9,Compras!F:F) -> 8 | G9: =E9/(4*12) -> 0.22916667 | H9: =F9/(4*12) -> 0.16666667
C10: Manguera dos vias NIBP para Monitor De Signos Vitales Cardiocap | D10: Manguera NIBP para Monitor De Signos Vitales Cardiocap | E10: =SUMIF(Compras!D:D,D10,Compras!E:E) -> 2 | F10: =SUMIF(Compras!D:D,Hoja2!D10,Compras!F:F) -> 2 | G10: =E10/(4*12) -> 0.041666667 | H10: =F10/(4*12) -> 0.041666667
C11: Brazalete Adulto 1 Via lavable reutilizable | D11: Brazalete Adulto 1 Via | E11: =SUMIF(Compras!D:D,D11,Compras!E:E) -> 43 | F11: =SUMIF(Compras!D:D,Hoja2!D11,Compras!F:F) -> 20 | G11: =E11/(4*12) -> 0.89583333 | H11: =F11/(4*12) -> 0.41666667
C12: Conector Para Brazalete plastico | D12: Conector Para Brazalete | E12: =SUMIF(Compras!D:D,D12,Compras!E:E) -> 37 | F12: =SUMIF(Compras!D:D,Hoja2!D12,Compras!F:F) -> 17 | G12: =E12/(4*12) -> 0.77083333 | H12: =F12/(4*12) -> 0.35416667
C13: Bateria Monitor Signos Vitales Mindray Mec1200 | D13: Bateria Monitor Signos Vitales Mindray Mec1200 | E13: =SUMIF(Compras!D:D,D13,Compras!E:E) -> 58 | F13: =SUMIF(Compras!D:D,Hoja2!D13,Compras!F:F) -> 25 | G13: =E13/(4*12) -> 1.2083333 | H13: =F13/(4*12) -> 0.52083333
C14: Sensor De Saturación Mindray MEC1200 Adulto Monitor de signos vitales | D14: Sensor De Saturación Mindray MEC1200 Adulto | E14: =SUMIF(Compras!D:D,D14,Compras!E:E) -> 88 | F14: =SUMIF(Compras!D:D,Hoja2!D14,Compras!F:F) -> 59 | G14: =E14/(4*12) -> 1.8333333 | H14: =F14/(4*12) -> 1.2291667
... C89: CABLE ECG 3 DERIVADAS MINDRAY PM8000 y Mec1200 Monitor de signos vitales | D89: CABLE ECG 3 DERIVADAS MINDRAY PM8000 y Mec1200 | E89: =SUMIF(Compras!D:D,D89,Compras!E:E) -> 3 | F89: =SUMIF(Compras!D:D,Hoja2!D89,Compras!F:F) -> 3 | G89: =E89/(4*12) -> 0.0625 | H89: =F89/(4*12) -> 0.0625
